Workbook

Sheet EXPAND CLONAL DATA
A1: CTRL D0 B | B1: CTRL D0 T | C1: CTRL D0 S | D1: CTRL D2 B | E1: CTRL D2 T | F1: CTRL D2 S | G1: EXP D2 B | H1: EXP D2 T | I1: EXP D2 S | J1: CTRL D4 B | K1: CTRL D4 T | L1: CTRL D4 S | M1: EXP D4 B | N1: EXP D4 T | O1: EXP D4 S | P1: CTRL D8 B | Q1: CTRL D8 T | R1: CTRL D8 S | S1: EXP D8 B | T1: EXP D8 T | U1: EXP D8 S | V1: CTRL D10 B | W1: CTRL D10 T | X1: CTRL D10 S | Y1: EXP D10 B | Z1: EXP D10 T | AA1: EXP D10 S | AB1: CTRL D14 B | AC1: CTRL D14 T | AD1: CTRL D14 S | AE1: EXP D14 B | AF1: EXP D14 T | AG1: EXP D14 S | AI1: CTRL D0 | AL1: distributions | BV1: cumulative distribution | CU1: fit | CV1: CTRL B | CW1: EXP B | CX1: =CV1 -> CTRL B | CY1: =CW1 -> EXP B | CZ1: 0.045 | DU1: 2 | DV1: =DU8 -> 0.97 | ET1: 2 | EU1: =ET8 -> 0.84 | GP1: =GP10 -> CTRL D2 B | GX1: =GX10 -> CTRL D4 B | HF1: =HF10 -> CTRL D8 B | HN1: =HN10 -> CTRL D10 B | HV1: =HV10 -> CTRL D14 B | IA1: dprob | IB1: 1 | IE1: =IE10 -> EXP D4 B | IJ1: dprob | IK1: 0.5 | IN1: =IN10 -> EXP D8 B | IS1: dprob | IT1: 0.5 | IW1: =IW10 -> EXP D10 B | JB1: dprob | JC1: 0.5 | JF1: =JF10 -> EXP D14 B | JK1: dprob | JL1: 0.5 | JP1: =JP10 -> EXP D14 T | JX1: proliferation rate
A2: 2 | B2: 2 | C2: =B2-A2 -> 0 | D2: 2 | E2: 2 | F2: =E2-D2 -> 0 | G2: 3 | H2: 3 | I2: =H2-G2 -> 0 | J2: 4 | K2: 4 | L2: =K2-J2 -> 0 | M2: 7 | N2: 7 | O2: =N2-M2 -> 0 | P2: 2 | Q2: 3 | R2: =Q2-P2 -> 1 | S2: 6 | T2: 8 | U2: =T2-S2 -> 2 | V2: 1 | W2: 1 | X2: =W2-V2 -> 0 | Y2: 2 | Z2: 2 | AA2: =Z2-Y2 -> 0 | AB2: 1 | AC2: 1 | AD2: =AC2-AB2 -> 0 | AE2: 16 | AF2: 30 | AG2: =AF2-AE2 -> 14 | AI2: BB | AJ2: =COUNTIFS(B$2:B$1000,2,A$2:A$1000,2) -> 57 | AL2: max | AM2: =MAX(A2:AF1000) -> 60 | BX2: CTRL B | BY2: CTRL T | BZ2: EXP B | CA2: EXP T | CE2: 1/l | CF2: =1/0.2289 -> 4.36872 | CI2: CTRL B | CJ2: CTRL T | CM2: EXP B | CN2: EXP T | CU2: 2 | CV2: =CB8 -> 0.77 | CW2: =CF8 -> 0.79 | CX2: =CI4 -> 1.7428571 | CY2: =CM4 -> 1.7922078 | CZ2: =1+CU2*CZ$1 -> 1.09 | DU2: 4 | DV2: =DZ8 -> 1.78 | ET2: 4 | EU2: =EY8 -> 0.91 | FQ2: distribution | IA2: dlr | IB2: 0.2 | IJ2: dlr | IK2: 0.35 | IS2: dlr | IT2: 0.29 | JB2: dlr | JC2: 0.09 | JK2: dlr | JL2: 0.053
A3: 2 | B3: 2 | C3: =B3-A3 -> 0 | D3: 1 | E3: 1 | F3: =E3-D3 -> 0 | G3: 2 | H3: 2 | I3: =H3-G3 -> 0 | J3: 5 | K3: 7 | L3: =K3-J3 -> 2 | M3: 3 | N3: 3 | O3: =N3-M3 -> 0 | P3: 4 | Q3: 6 | R3: =Q3-P3 -> 2 | S3: 8 | T3: 10 | U3: =T3-S3 -> 2 | V3: 1 | W3: 1 | X3: =W3-V3 -> 0 | Y3: 2 | Z3: 4 | AA3: =Z3-Y3 -> 2 | AB3: 3 | AC3: 3 | AD3: =AC3-AB3 -> 0 | AE3: 44 | AF3: 60 | AG3: =AF3-AE3 -> 16 | AI3: BS | AJ3: =COUNTIFS(B$2:B$1000,2,A$2:A$1000,1) -> 0 | AM3: time | AN3: 0 | AO3: 0 | AP3: 0 | AQ3: 2 | AR3: 2 | AS3: 2 | AT3: 2 | AU3: 2 | AV3: 2 | AW3: 4 | AX3: 4 | AY3: 4 | AZ3: 4 | BA3: 4 | BB3: 4 | BC3: 8 | BD3: 8 | BE3: 8 | BF3: 8 | BG3: 8 | BH3: 8 | BI3: 10 | BJ3: 10 | BK3: 10 | BL3: 10 | BM3: 10 | BN3: 10 | BO3: 14 | BP3: 14 | BQ3: 14 | BR3: 14 | BS3: 14 | BT3: 14 | BW3: 0 | BX3: =AN6 -> 142.43199 | BY3: =AO6 -> 142.43199 | CF3: =1/0.0785 -> 12.738854 | CH3: 0 | CI3: =AN4 -> 1.5391304 | CJ3: =AO4 -> 1.5391304 | CU3: 4 | CV3: =CK8 -> 1.17 | CW3: =CO8 -> 2.08 | CX3: =CI5 -> 2.2867647 | CY3: =CM5 -> 3.0456853 | CZ3: =1+CU3*CZ$1 -> 1.18 | DU3: 8 | DV3: =EE8 -> 2.29 | ET3: 8 | EU3: =FD8 -> 1.05 | FQ3: =AM3 -> time | FR3: =AN3 -> 0 | FS3: =AO3 -> 0 | FT3: =AQ3 -> 2 | FU3: =AR3 -> 2 | FV3: =AT3 -> 2 | FW3: =AU3 -> 2 | FX3: =AW3 -> 4 | FY3: =AX3 -> 4 | FZ3: =AZ3 -> 4 | GA3: =BA3 -> 4 | GB3: =BC3 -> 8 | GC3: =BD3 -> 8 | GD3: =BF3 -> 8 | GE3: =BG3 -> 8 | GF3: =BI3 -> 10 | GG3: =BJ3 -> 10 | GH3: =BL3 -> 10 | GI3: =BM3 -> 10 | GJ3: =BO3 -> 14 | GK3: =BP3 -> 14 | GL3: =BR3 -> 14 | GM3: =BS3 -> 14 | IA3: dasym | IB3: 0.52 | IJ3: dasym | IK3: 0.52 | IS3: dasym | IT3: 0.56 | JB3: dasym | JC3: 0.65 | JK3: dasym | JL3: 0.49 | JZ3: effective time | KA3: effective time
A4: 2 | B4: 2 | C4: =B4-A4 -> 0 | D4: 2 | E4: 2 | F4: =E4-D4 -> 0 | G4: 1 | H4: 1 | I4: =H4-G4 -> 0 | J4: 4 | K4: 4 | L4: =K4-J4 -> 0 | M4: 4 | N4: 4 | O4: =N4-M4 -> 0 | P4: 2 | Q4: 5 | R4: =Q4-P4 -> 3 | S4: 7 | T4: 10 | U4: =T4-S4 -> 3 | V4: 1 | W4: 1 | X4: =W4-V4 -> 0 | Y4: 6 | Z4: 10 | AA4: =Z4-Y4 -> 4 | AB4: 2 | AC4: 4 | AD4: =AC4-AB4 -> 2 | AE4: 10 | AF4: 14 | AG4: =AF4-AE4 -> 4 | AI4: SS | AJ4: =COUNTIFS(B$2:B$1000,2,A$2:A$1000,0) -> 0 | AM4: average | AN4: =AVERAGE(A2:A1000) -> 1.5391304 | AO4: =AVERAGE(B2:B1000) -> 1.5391304 | AP4: =AVERAGE(C2:C1000) -> 0 | AQ4: =AVERAGE(D2:D1000) -> 1.7428571 | AR4: =AVERAGE(E2:E1000) -> 1.8285714 | AS4: =AVERAGE(F2:F1000) -> 0.085714286 | AT4: =AVERAGE(G2:G1000) -> 1.7922078 | AU4: =AVERAGE(H2:H1000) -> 1.9134199 | ... BT4: =AVERAGE(AG2:AG1000) -> 5.2914573 | BW4: 2 | BX4: =AQ6 -> 152.85918 | BY4: =AR6 -> 160.37685 | BZ4: =AT6 -> 137.01645 | CA4: =AU6 -> 146.28327 | CE4: t0 | CF4: =0.52/0.2289 -> 2.2717344 | CH4: 2 | CI4: =AQ4 -> 1.7428571 | CJ4: =AR4 -> 1.8285714 | CM4: =AT4 -> 1.7922078 | CN4: =AU4 -> 1.9134199 | CQ4: =CJ4/CI4 -> 1.0491803 | CR4: =CN4/CM4 -> 1.0676329 | CU4: 8 | CV4: =CT8 -> 1.27 | CW4: =CX8 -> 2.42 | CX4: =CI6 -> 2.1949686 | CY4: =CM6 -> 3.5376884 | CZ4: =1+CU4*CZ$1 -> 1.36 | DU4: 10 | DV4: =EJ8 -> 4 | ET4: 10 | EU4: =FI8 -> 1.21 | FQ4: =AM4 -> average | FR4: =AN4 -> 1.5391304 | FS4: =AO4 -> 1.5391304 | FT4: =AQ4 -> 1.7428571 | FU4: =AR4 -> 1.8285714 | FV4: =AT4 -> 1.7922078 | FW4: =AU4 -> 1.9134199 | FX4: =AW4 -> 2.2867647 | FY4: =AX4 -> 2.7573529 | FZ4: =AZ4 -> 3.0456853 | GA4: =BA4 -> 3.6649746 | GB4: =BC4 -> 2.1949686 | GC4: =BD4 -> 3.0691824 | GD4: =BF4 -> 3.5376884 | GE4: =BG4 -> 6.0452261 | GF4: =BI4 -> 2.4315068 | GG4: =BJ4 -> 3.8082192 | GH4: =BL4 -> 5.3248408 | GI4: =BM4 -> 9.5541401 | GJ4: =BO4 -> 2.7384615 | GK4: =BP4 -> 4.8153846 | GL4: =BR4 -> 5.080402 | GM4: =BS4 -> 10.371859 | GP4: n0 | GQ4: 1.32 | GT4: average | GU4: =FT4 -> 1.7428571 | GX4: n0 | GY4: 1.32 | HB4: average | HC4: =FX4 -> 2.2867647 | HF4: n0 | HG4: 1.32 | HJ4: average | HK4: =GB4 -> 2.1949686 | HN4: n0 | HO4: 1.67 | HR4: average | HS4: =GF4 -> 2.4315068 | HV4: n0 | HW4: 2.26 | HZ4: average | IA4: =GJ4 -> 2.7384615 | IB4: 2.78 | IE4: n0 | IF4: 3 | II4: average | IJ4: =FZ4 -> 3.0456853 | IK4: 3.07 | IN4: n0 | IO4: 3.5 | IR4: average | IS4: =GD4 -> 3.5376884 | IT4: 3.52 | IW4: n0 | IX4: 5.2 | JA4: average | JB4: =GH4 -> 5.3248408 | JC4: 5.38 | JF4: n0 | JG4: 4.28 | JJ4: average | JK4: =GL4 -> 5.080402 | JL4: 5.09 | JP4: n0 | JQ4: 12.5 | JT4: average | JU4: =GM4 -> 10.371859 | JW4: 0 | JX4: 3.2 | JY4: 4 | JZ4: 0 | KA4: 0
A5: 1 | B5: 1 | C5: =B5-A5 -> 0 | D5: 1 | E5: 2 | F5: =E5-D5 -> 1 | G5: 1 | H5: 1 | I5: =H5-G5 -> 0 | J5: 2 | K5: 3 | L5: =K5-J5 -> 1 | M5: 2 | N5: 2 | O5: =N5-M5 -> 0 | P5: 2 | Q5: 4 | R5: =Q5-P5 -> 2 | S5: 3 | T5: 5 | U5: =T5-S5 -> 2 | V5: 3 | W5: 3 | X5: =W5-V5 -> 0 | Y5: 6 | Z5: 6 | AA5: =Z5-Y5 -> 0 | AB5: 2 | AC5: 8 | AD5: =AC5-AB5 -> 6 | AE5: 24 | AF5: 32 | AG5: =AF5-AE5 -> 8 | AM5: persistence | AN5: ='EXPAND PERSISTANCE'!A14 -> 92.540559 | AO5: =AN5 -> 92.540559 | AP5: =AO5 -> 92.540559 | AQ5: ='EXPAND PERSISTANCE'!B14 -> 87.706089 | AR5: =AQ5 -> 87.706089 | AS5: =AR5 -> 87.706089 | AT5: ='EXPAND PERSISTANCE'!C14 -> 76.45121 | AU5: =AT5 -> 76.45121 | AV5: =AU5 -> 76.45121 | AW5: ='EXPAND PERSISTANCE'!D14 -> 84.098068 | AX5: =AW5 -> 84.098068 | AY5: =AX5 -> 84.098068 | AZ5: ='EXPAND PERSISTANCE'!E14 -> 80.600055 | BA5: =AZ5 -> 80.600055 | BB5: =BA5 -> 80.600055 | BC5: ='EXPAND PERSISTANCE'!F14 -> 66.433793 | BD5: =BC5 -> 66.433793 | BE5: =BD5 -> 66.433793 | BF5: ='EXPAND PERSISTANCE'!G14 -> 68.900262 | BG5: =BF5 -> 68.900262 | BH5: =BG5 -> 68.900262 | BI5: ='EXPAND PERSISTANCE'!H14 -> 66.511783 | BJ5: =BI5 -> 66.511783 | BK5: =BJ5 -> 66.511783 | BL5: ='EXPAND PERSISTANCE'!I14 -> 56.408253 | BM5: =BL5 -> 56.408253 | BN5: =BM5 -> 56.408253 | BO5: ='EXPAND PERSISTANCE'!J14 -> 62.246988 | BP5: =BO5 -> 62.246988 | BQ5: =BP5 -> 62.246988 | BR5: ='EXPAND PERSISTANCE'!K14 -> 46.6853 | BS5: =BR5 -> 46.6853 | BT5: =BS5 -> 46.6853 | BW5: 4 | BX5: =AW6 -> 192.31249 | BY5: =AX6 -> 231.88806 | BZ5: =AZ6 -> 245.4824 | CA5: =BA6 -> 295.39716 | CE5: rho | CF5: 0.5 | CH5: 4 | CI5: =AW4 -> 2.2867647 | CJ5: =AX4 -> 2.7573529 | CM5: =AZ4 -> 3.0456853 | CN5: =BA4 -> 3.6649746 | CQ5: =CJ5/CI5 -> 1.2057878 | CR5: =CN5/CM5 -> 1.2033333 | CU5: 10 | CV5: =DC8 -> 1.37 | CW5: =DG8 -> 4 | CX5: =CI7 -> 2.4315068 | CY5: =CM7 -> 5.3248408 | CZ5: =1+CU5*CZ$1 -> 1.45 | DU5: 14 | DV5: =EO8 -> 3.65 | ET5: 14 | EU5: =FN8 -> 1.5 | FQ5: =AM5 -> persistence | FR5: =AN5 -> 92.540559 | FS5: =AO5 -> 92.540559 | FT5: =AQ5 -> 87.706089 | FU5: =AR5 -> 87.706089 | FV5: =AT5 -> 76.45121 | FW5: =AU5 -> 76.45121 | FX5: =AW5 -> 84.098068 | FY5: =AX5 -> 84.098068 | FZ5: =AZ5 -> 80.600055 | GA5: =BA5 -> 80.600055 | GB5: =BC5 -> 66.433793 | GC5: =BD5 -> 66.433793 | GD5: =BF5 -> 68.900262 | GE5: =BG5 -> 68.900262 | GF5: =BI5 -> 66.511783 | GG5: =BJ5 -> 66.511783 | GH5: =BL5 -> 56.408253 | GI5: =BM5 -> 56.408253 | GJ5: =BO5 -> 62.246988 | GK5: =BP5 -> 62.246988 | GL5: =BR5 -> 46.6853 | GM5: =BS5 -> 46.6853 | GP5: b | GQ5: 0.49 | GT5: m | GU5: =SUM(GU11:GU110)/100 -> 0.0057142857 | GX5: b | GY5: 0.49 | HB5: m | HC5: =SUM(HC11:HC110)/100 -> 0.30882353 | HF5: b | HG5: 0.49 | HJ5: m | HK5: =SUM(HK11:HK110)/100 -> 0.10691824 | HN5: b | HO5: 0.64 | HR5: m | HS5: =SUM(HS11:HS110)/100 -> 0.32876712 | HV5: b | HW5: 0.5 | HZ5: m | IA5: =SUM(IA11:IA110)/100 -> 0.3025641 | IB5: 0.32 | IE5: b | IF5: 0.32 | II5: m | IJ5: =SUM(IJ11:IJ110)/100 -> 0.086294416 | IK5: 0.082 | IN5: b | IO5: 0.37 | IR5: m | IS5: =SUM(IS11:IS110)/100 -> 0.1758794 | IT5: 0.16 | IW5: b | IX5: 0.59 | JA5: m | JB5: =SUM(JB11:JB110)/100 -> 0.51592357 | JC5: 0.52 | JF5: b | JG5: 0.735 | JJ5: m | JK5: =SUM(JK11:JK110)/100 -> 0.68844221 | JL5: 0.69 | JP5: b | JQ5: 0.68 | JT5: m | JU5: =SUM(JU11:JU110)/100 -> 0.61809045 | JW5: 1 | JX5: 3.2 | JY5: 4 | JZ5: =(JX5+JX4)/JX$4*($JW5-$JW4)/2+JZ4 -> 1 | KA5: =KA4+JY5/JY$4*(JW5-JW4) -> 1 | KB5: 0.17
A6: 1 | B6: 1 | C6: =B6-A6 -> 0 | D6: 1 | E6: 1 | F6: =E6-D6 -> 0 | G6: 1 | H6: 1 | I6: =H6-G6 -> 0 | J6: 3 | K6: 6 | L6: =K6-J6 -> 3 | M6: 1 | N6: 1 | O6: =N6-M6 -> 0 | P6: 1 | Q6: 2 | R6: =Q6-P6 -> 1 | S6: 3 | T6: 3 | U6: =T6-S6 -> 0 | V6: 1 | W6: 1 | X6: =W6-V6 -> 0 | Y6: 5 | Z6: 5 | AA6: =Z6-Y6 -> 0 | AB6: 4 | AC6: 8 | AD6: =AC6-AB6 -> 4 | AE6: 12 | AF6: 20 | AG6: =AF6-AE6 -> 8 | AI6: CTRL D2 | AM6: product | AN6: =AN4*AN5 -> 142.43199 | AO6: =AO4*AO5 -> 142.43199 | AP6: =AP4*AP5 -> 0 | AQ6: =AQ4*AQ5 -> 152.85918 | AR6: =AR4*AR5 -> 160.37685 | AS6: =AS4*AS5 -> 7.5176647 | AT6: =AT4*AT5 -> 137.01645 | AU6: =AU4*AU5 -> 146.28327 | ... BT6: =BT4*BT5 -> 247.03327 | BW6: 8 | BX6: =BC6 -> 145.82009 | BY6: =BD6 -> 203.89743 | BZ6: =BF6 -> 243.74766 | CA6: =BG6 -> 416.51767 | CE6: r | CF6: =0.0785*CF2*CF5 -> 0.17147226 | CG6: =1/CF6 -> 5.8318471 | CH6: 8 | CI6: =BC4 -> 2.1949686 | CJ6: =BD4 -> 3.0691824 | CM6: =BF4 -> 3.5376884 | CN6: =BG4 -> 6.0452261 | CQ6: =CJ6/CI6 -> 1.3982808 | CR6: =CN6/CM6 -> 1.7088068 | CU6: 14 | CV6: =DL8 -> 1.63 | CW6: =DP8 -> 3.53 | CX6: =CI8 -> 2.7384615 | CY6: =CM8 -> 5.080402 | CZ6: =1+CU6*CZ$1 -> 1.63 | FQ6: =AM6 -> product | FR6: =AN6 -> 142.43199 | FS6: =AO6 -> 142.43199 | FT6: =AQ6 -> 152.85918 | FU6: =AR6 -> 160.37685 | FV6: =AT6 -> 137.01645 | FW6: =AU6 -> 146.28327 | FX6: =AW6 -> 192.31249 | FY6: =AX6 -> 231.88806 | FZ6: =AZ6 -> 245.4824 | GA6: =BA6 -> 295.39716 | GB6: =BC6 -> 145.82009 | GC6: =BD6 -> 203.89743 | GD6: =BF6 -> 243.74766 | GE6: =BG6 -> 416.51767 | GF6: =BI6 -> 161.72386 | GG6: =BJ6 -> 253.29145 | GH6: =BL6 -> 300.36496 | GI6: =BM6 -> 538.93235 | GJ6: =BO6 -> 170.46098 | GK6: =BP6 -> 299.74319 | GL6: =BR6 -> 237.18009 | GM6: =BS6 -> 484.21336 | GP6: a | GQ6: =(EXP(2/GQ$4)-1)/(1+GQ$5+EXP(1/GQ$4)*(1-GQ$5))*100 -> 137.71432 | GX6: a | GY6: =(EXP(2/GY$4)-1)/(1+GY$5+EXP(1/GY$4)*(1-GY$5))*100 -> 137.71432 | HF6: a | HG6: =(EXP(2/HG$4)-1)/(1+HG$5+EXP(1/HG$4)*(1-HG$5))*100 -> 137.71432 | HN6: a | HO6: =(EXP(2/HO$4)-1)/(1+HO$5+EXP(1/HO$4)*(1-HO$5))*100 -> 100.74053 | HV6: a | HW6: =(EXP(2/HW$4)-1)/(1+HW$5+EXP(1/HW$4)*(1-HW$5))*100 -> 62.454017 | IE6: a | IF6: =(EXP(2/IF$4)-1)/(1+IF$5+EXP(1/IF$4)*(1-IF$5))*100 -> 41.768496 | IN6: a | IO6: =(EXP(2/IO$4)-1)/(1+IO$5+EXP(1/IO$4)*(1-IO$5))*100 -> 34.90368 | IW6: a | IX6: =(EXP(2/IX$4)-1)/(1+IX$5+EXP(1/IX$4)*(1-IX$5))*100 -> 22.475476 | JF6: a | JG6: =(EXP(2/JG$4)-1)/(1+JG$5+EXP(1/JG$4)*(1-JG$5))*100 -> 28.77954 | JP6: a | JQ6: =(EXP(2/JQ$4)-1)/(1+JQ$5+EXP(1/JQ$4)*(1-JQ$5))*100 -> 8.5614542 | JW6: 2 | JX6: 8 | JY6: 4 | JZ6: =(JX6+JX5)/JX$4*($JW6-$JW5)/2+JZ5 -> 2.75 | KA6: =KA5+JY6/JY$4*(JW6-JW5) -> 2 | KB6: 0.4
A7: 2 | B7: 2 | C7: =B7-A7 -> 0 | D7: 1 | E7: 1 | F7: =E7-D7 -> 0 | G7: 3 | H7: 3 | I7: =H7-G7 -> 0 | J7: 5 | K7: 7 | L7: =K7-J7 -> 2 | M7: 1 | N7: 1 | O7: =N7-M7 -> 0 | P7: 4 | Q7: 4 | R7: =Q7-P7 -> 0 | S7: 5 | T7: 5 | U7: =T7-S7 -> 0 | V7: 5 | W7: 8 | X7: =W7-V7 -> 3 | Y7: 6 | Z7: 6 | AA7: =Z7-Y7 -> 0 | AB7: 3 | AC7: 6 | AD7: =AC7-AB7 -> 3 | AE7: 4 | AF7: 12 | AG7: =AF7-AE7 -> 8 | AI7: BB | AJ7: =COUNTIFS(E$2:E$1000,2,D$2:D$1000,2) -> 80 | BW7: 10 | BX7: =BI6 -> 161.72386 | BY7: =BJ6 -> 253.29145 | BZ7: =BL6 -> 300.36496 | CA7: =BM6 -> 538.93235 | CB7: 209 | CF7: 209 | CH7: 10 | CI7: =BI4 -> 2.4315068 | CJ7: =BJ4 -> 3.8082192 | CK7: 178 | CM7: =BL4 -> 5.3248408 | CN7: =BM4 -> 9.5541401 | CO7: 133 | CQ7: =CJ7/CI7 -> 1.5661972 | CR7: =CN7/CM7 -> 1.7942584 | CT7: 147 | CX7: 134.8 | DC7: 160 | DG7: 120.5 | DK7: amp | DL7: 150 | DO7: amp | DP7: 122 | DU7: 163 | DZ7: 158 | EE7: 142 | EJ7: 120 | EO7: 120 | ET7: 183 | EY7: 245 | FD7: 178 | FI7: 186 | FN7: 170 | GK7: =GK6/GJ6 -> 1.758427 | JW7: 4 | JX7: 8 | JY7: 4 | JZ7: =(JX7+JX6)/JX$4*($JW7-$JW6)/2+JZ6 -> 7.75 | KA7: =KA6+JY7/JY$4*(JW7-JW6) -> 4 | KB7: 0.5
A8: 1 | B8: 1 | C8: =B8-A8 -> 0 | D8: 1 | E8: 1 | F8: =E8-D8 -> 0 | G8: 2 | H8: 2 | I8: =H8-G8 -> 0 | J8: 4 | K8: 4 | L8: =K8-J8 -> 0 | M8: 1 | N8: 1 | O8: =N8-M8 -> 0 | P8: 1 | Q8: 1 | R8: =Q8-P8 -> 0 | S8: 6 | T8: 8 | U8: =T8-S8 -> 2 | V8: 1 | W8: 5 | X8: =W8-V8 -> 4 | Y8: 3 | Z8: 3 | AA8: =Z8-Y8 -> 0 | AB8: 6 | AC8: 12 | AD8: =AC8-AB8 -> 6 | AE8: 6 | AF8: 14 | AG8: =AF8-AE8 -> 8 | AI8: BS | AJ8: =COUNTIFS(E$2:E$1000,2,D$2:D$1000,1) -> 4 | BW8: 14 | BX8: =BO6 -> 170.46098 | BY8: =BP6 -> 299.74319 | BZ8: =BR6 -> 237.18009 | CA8: =BS6 -> 484.21336 | CB8: 0.77 | CC8: =SUM(CC11:CC110) -> 11902.82 | CF8: 0.79 | CG8: =SUM(CG11:CG110) -> 11982.937 | CH8: 14 | CI8: =BO4 -> 2.7384615 | CJ8: =BP4 -> 4.8153846 | CK8: 1.17 | CL8: =SUM(CL11:CL110) -> 6160.4442 | CM8: =BR4 -> 5.080402 | CN8: =BS4 -> 10.371859 | CO8: 2.08 | CP8: =SUM(CP11:CP110) -> 1171.8471 | CQ8: =CJ8/CI8 -> 1.758427 | CR8: =CN8/CM8 -> 2.041543 | CT8: 1.27 | CU8: =SUM(CU11:CU110) -> 2239.1756 | CX8: 2.42 | CY8: =SUM(CY11:CY110) -> 1297.0778 | DC8: 1.37 | DD8: =SUM(DD11:DD110) -> 3683.5742 | DG8: 4 | DH8: =SUM(DH11:DH110) -> 563.33433 | DK8: exp | DL8: 1.63 | DM8: =SUM(DM11:DM110) -> 2546.2862 | DO8: exp | DP8: 3.53 | DQ8: =SUM(DQ11:DQ110) -> 648.56259 | DU8: 0.97 | DZ8: 1.78 | EE8: 2.29 | EJ8: 4 | EO8: 3.65 | ET8: 0.84 | EY8: 0.91 | FD8: 1.05 | FI8: 1.21 | FN8: 1.5 | GK8: =5/3 -> 1.6666667 | JW8: 8 | JX8: 6.5 | JY8: 4 | JZ8: =(JX8+JX7)/JX$4*($JW8-$JW7)/2+JZ7 -> 16.8125 | KA8: =KA7+JY8/JY$4*(JW8-JW7) -> 8 | KB8: 0.17
A9: 1 | B9: 1 | C9: =B9-A9 -> 0 | D9: 2 | E9: 2 | F9: =E9-D9 -> 0 | G9: 1 | H9: 1 | I9: =H9-G9 -> 0 | J9: 2 | K9: 2 | L9: =K9-J9 -> 0 | M9: 4 | N9: 4 | O9: =N9-M9 -> 0 | P9: 1 | Q9: 1 | R9: =Q9-P9 -> 0 | S9: 1 | T9: 3 | U9: =T9-S9 -> 2 | V9: 4 | W9: 4 | X9: =W9-V9 -> 0 | Y9: 7 | Z9: 10 | AA9: =Z9-Y9 -> 3 | AB9: 2 | AC9: 4 | AD9: =AC9-AB9 -> 2 | AE9: 10 | AF9: 20 | AG9: =AF9-AE9 -> 10 | AI9: SS | AJ9: =COUNTIFS(E$2:E$1000,2,D$2:D$1000,0) -> 0 | AN9: =SUM(AN10:AN110) -> 115 | AO9: =SUM(AO10:AO110) -> 115 | AP9: =SUM(AP10:AP110) -> 115 | AQ9: =SUM(AQ10:AQ110) -> 175 | AR9: =SUM(AR10:AR110) -> 175 | AS9: =SUM(AS10:AS110) -> 175 | AT9: =SUM(AT10:AT110) -> 231 | AU9: =SUM(AU10:AU110) -> 231 | ... BT9: =SUM(BT10:BT110) -> 199 | GQ9: =SUM(GQ11:GQ110) -> 305.19434 | GR9: =SUM(GR11:GR110) -> 42229.645 | GS9: =(1/16)*SUM(GS11:GS26) -> 9.5395666 | GT9: =(1/16/GS9)*SUM(GT11:GT26) -> 0.086982546 | GY9: =SUM(GY11:GY110) -> 305.19434 | GZ9: =SUM(GZ11:GZ110) -> 42276.636 | HA9: =(1/16)*SUM(HA11:HA26) -> 11.031009 | HB9: =(1/16/HA9)*SUM(HB11:HB26) -> 0.38126692 | HG9: =SUM(HG11:HG110) -> 305.19434 | HH9: =SUM(HH11:HH110) -> 42130.719 | HI9: =(1/16)*SUM(HI11:HI26) -> 10.968468 | HJ9: =(1/16/HI9)*SUM(HJ11:HJ26) -> 0.20628035 | HO9: =SUM(HO11:HO110) -> 265.21446 | HP9: =SUM(HP11:HP110) -> 27336.569 | HQ9: =(1/16)*SUM(HQ11:HQ26) -> 11.501693 | HR9: =(1/16/HQ9)*SUM(HR11:HR26) -> 0.3445322 | HW9: =SUM(HW11:HW110) -> 193.68102 | HX9: =SUM(HX11:HX110) -> 8818.2706 | HY9: =(1/16)*SUM(HY11:HY26) -> 12.784068 | HZ9: =(1/16/HY9)*SUM(HZ11:HZ26) -> 0.40660006 | IF9: =SUM(IF11:IF110) -> 155.13441 | IG9: =SUM(IG11:IG110) -> 3154.5919 | IH9: =(1/16)*SUM(IH11:IH26) -> 13.91643 | II9: =(1/16/IH9)*SUM(II11:II26) -> 0.15777028 | IO9: =SUM(IO11:IO110) -> 147.81804 | IP9: =SUM(IP11:IP110) -> 2354.6102 | IQ9: =(1/16)*SUM(IQ11:IQ26) -> 16.654407 | IR9: =(1/16/IQ9)*SUM(IR11:IR26) -> 0.22525505 | IX9: =SUM(IX11:IX110) -> 135.73601 | IY9: =SUM(IY11:IY110) -> 1380.4674 | IZ9: =(1/16)*SUM(IZ11:IZ26) -> 25.134764 | JA9: =(1/16/IZ9)*SUM(JA11:JA26) -> 0.57118773 | JG9: =SUM(JG11:JG110) -> 149.9325 | JH9: =SUM(JH11:JH110) -> 2520.512 | JI9: =(1/16)*SUM(JI11:JI26) -> 22.316292 | JJ9: =(1/16/JI9)*SUM(JJ11:JJ26) -> 0.75221551 | JQ9: =SUM(JQ11:JQ110) -> 114.34487 | JR9: =SUM(JR11:JR110) -> 326.60865 | JS9: =(1/16)*SUM(JS11:JS26) -> 39.852186 | JT9: =(1/16/JS9)*SUM(JT11:JT26) -> 0.68979956 | JW9: 10 | JX9: 6.1 | JY9: 4 | JZ9: =(JX9+JX8)/JX$4*($JW9-$JW8)/2+JZ8 -> 20.75 | KA9: =KA8+JY9/JY$4*(JW9-JW8) -> 10 | KB9: 0.12
A10: 1 | B10: 1 | C10: =B10-A10 -> 0 | D10: 1 | E10: 1 | F10: =E10-D10 -> 0 | G10: 2 | H10: 2 | I10: =H10-G10 -> 0 | J10: 3 | K10: 3 | L10: =K10-J10 -> 0 | M10: 3 | N10: 3 | O10: =N10-M10 -> 0 | P10: 2 | Q10: 4 | R10: =Q10-P10 -> 2 | S10: 1 | T10: 1 | U10: =T10-S10 -> 0 | V10: 3 | W10: 8 | X10: =W10-V10 -> 5 | Y10: 5 | Z10: 10 | AA10: =Z10-Y10 -> 5 | AB10: 4 | AC10: 7 | AD10: =AC10-AB10 -> 3 | AE10: 1 | AF10: 3 | AG10: =AF10-AE10 -> 2 | AN10: =A1 -> CTRL D0 B | AO10: =B1 -> CTRL D0 T | AP10: =C1 -> CTRL D0 S | AQ10: =D1 -> CTRL D2 B | AR10: =E1 -> CTRL D2 T | AS10: =F1 -> CTRL D2 S | AT10: =G1 -> EXP D2 B | AU10: =H1 -> EXP D2 T | ... BT10: =AG1 -> EXP D14 S | BX10: =AN10 -> CTRL D0 B | BY10: =AO10 -> CTRL D0 T | BZ10: =AQ10 -> CTRL D2 B | CA10: =AR10 -> CTRL D2 T | CB10: exp | CD10: =AT10 -> EXP D2 B | CE10: =AU10 -> EXP D2 T | CF10: exp | CI10: =AW10 -> CTRL D4 B | CJ10: =AX10 -> CTRL D4 T | CK10: exp | CM10: =AZ10 -> EXP D4 B | CN10: =BA10 -> EXP D4 T | CO10: exp | CR10: =BC10 -> CTRL D8 B | CS10: =BD10 -> CTRL D8 T | CT10: exp | CV10: =BF10 -> EXP D8 B | CW10: =BG10 -> EXP D8 T | CX10: exp | DA10: =BI10 -> CTRL D10 B | DB10: =BJ10 -> CTRL D10 T | DC10: exp | DE10: =BL10 -> EXP D10 B | DF10: =BM10 -> EXP D10 T | DG10: exp | DJ10: =BO10 -> CTRL D14 B | DK10: =BP10 -> CTRL D14 T | DL10: exp | DN10: =BR10 -> EXP D14 B | DO10: =BS10 -> EXP D14 T | DP10: exp | DT10: =CD10 -> EXP D2 B | DU10: exp | DV10: =SQRT(SUM(DV11:DV110)) -> 63.597721 | DY10: =CM10 -> EXP D4 B | DZ10: exp | EA10: =SQRT(SUM(EA11:EA110)) -> 59.334162 | ED10: =CV10 -> EXP D8 B | EE10: exp | EF10: =SQRT(SUM(EF11:EF110)) -> 43.201396 | EI10: =DE10 -> EXP D10 B | EJ10: exp | EK10: =SQRT(SUM(EK11:EK110)) -> 23.31203 | EN10: =DN10 -> EXP D14 B | EO10: exp | EP10: =SQRT(SUM(EP11:EP110)) -> 23.678601 | ES10: =BZ10 -> CTRL D2 B | ET10: exp | EU10: =SQRT(SUM(EU11:EU110)) -> 83.279366 | EX10: =CI10 -> CTRL D4 B | EY10: exp | EZ10: =SQRT(SUM(EZ11:EZ110)) -> 145.57191 | FC10: =CR10 -> CTRL D8 B | FD10: exp | FE10: =SQRT(SUM(FE11:FE110)) -> 78.305375 | FH10: =DA10 -> CTRL D10 B | FI10: exp | FJ10: =SQRT(SUM(FJ11:FJ110)) -> 86.358085 | FM10: =DJ10 -> CTRL D14 B | FN10: exp | FO10: =SQRT(SUM(FO11:FO110)) -> 70.657104 | FR10: =AN10 -> CTRL D0 B | FS10: =AO10 -> CTRL D0 T | FT10: =AQ10 -> CTRL D2 B | FU10: =AR10 -> CTRL D2 T | FV10: =AT10 -> EXP D2 B | FW10: =AU10 -> EXP D2 T | FX10: =AW10 -> CTRL D4 B | FY10: =AX10 -> CTRL D4 T | FZ10: =AZ10 -> EXP D4 B | GA10: =BA10 -> EXP D4 T | GB10: =BC10 -> CTRL D8 B | GC10: =BD10 -> CTRL D8 T | GD10: =BF10 -> EXP D8 B | GE10: =BG10 -> EXP D8 T | GF10: =BI10 -> CTRL D10 B | GG10: =BJ10 -> CTRL D10 T | GH10: =BL10 -> EXP D10 B | GI10: =BM10 -> EXP D10 T | GJ10: =BO10 -> CTRL D14 B | GK10: =BP10 -> CTRL D14 T | GL10: =BR10 -> EXP D14 B | GM10: =BS10 -> EXP D14 T | GP10: =FT10 -> CTRL D2 B | GQ10: exp | GR10: square | GS10: a est | GT10: b est | GX10: =FX10 -> CTRL D4 B | GY10: exp | GZ10: square | HA10: a est | HB10: b est | HF10: =GB10 -> CTRL D8 B | HG10: exp | HH10: square | HI10: a est | HJ10: b est | HN10: =GF10 -> CTRL D10 B | HO10: exp | HP10: square | HQ10: a est | HR10: b est | HV10: =GJ10 -> CTRL D14 B | HW10: exp | HX10: square | HY10: a est | HZ10: b est | IB10: theory | IE10: =FZ10 -> EXP D4 B | IF10: exp | IG10: square | IH10: a est | II10: b est | IK10: theory | IN10: =GD10 -> EXP D8 B | IO10: exp | IP10: square | IQ10: a est | IR10: b est | IT10: theory | IW10: =GH10 -> EXP D10 B | IX10: exp | IY10: square | IZ10: a est | JA10: b est | JC10: theory | JF10: =GL10 -> EXP D14 B | JG10: exp | JH10: square | JI10: a est | JJ10: b est | JL10: theory | JP10: =GM10 -> EXP D14 T | JQ10: exp | JR10: square | JS10: a est | JT10: b est | JW10: 14 | JX10: 5 | JY10: 4 | JZ10: =(JX10+JX9)/JX$4*($JW10-$JW9)/2+JZ9 -> 27.6875 | KA10: =KA9+JY10/JY$4*(JW10-JW9) -> 14 | KB10: 0.05
A11: 2 | B11: 2 | C11: =B11-A11 -> 0 | D11: 1 | E11: 1 | F11: =E11-D11 -> 0 | G11: 2 | H11: 2 | I11: =H11-G11 -> 0 | J11: 2 | K11: 4 | L11: =K11-J11 -> 2 | M11: 3 | N11: 3 | O11: =N11-M11 -> 0 | P11: 2 | Q11: 3 | R11: =Q11-P11 -> 1 | S11: 6 | T11: 12 | U11: =T11-S11 -> 6 | V11: 4 | W11: 6 | X11: =W11-V11 -> 2 | Y11: 4 | Z11: 7 | AA11: =Z11-Y11 -> 3 | AB11: 4 | AC11: 6 | AD11: =AC11-AB11 -> 2 | AE11: 2 | AF11: 6 | AG11: =AF11-AE11 -> 4 | AI11: EXP D2 | AM11: 0 | AN11: {=FREQUENCY(A2:A1000,$AM11:$AM110)} -> 0 | AO11: {=FREQUENCY(B2:B1000,$AM11:$AM110)} -> 0 | AP11: {=FREQUENCY(C2:C1000,$AM11:$AM110)} -> 115 | AQ11: {=FREQUENCY(D2:D1000,$AM11:$AM110)} -> 0 | AR11: {=FREQUENCY(E2:E1000,$AM11:$AM110)} -> 0 | AS11: {=FREQUENCY(F2:F1000,$AM11:$AM110)} -> 165 | AT11: {=FREQUENCY(G2:G1000,$AM11:$AM110)} -> 1 | AU11: {=FREQUENCY(H2:H1000,$AM11:$AM110)} -> 0 | ... BT11: {=FREQUENCY(AG2:AG1000,$AM11:$AM110)} -> 36 | BW11: =$AM11 -> 0 | BX11: =MAX(100-AN11/AN$9*100,0) -> 100 | BY11: =MAX(100-AO11/AO$9*100,0) -> 100 | BZ11: =MAX(100-AQ11/AQ$9*100,0) -> 100 | CA11: =MAX(100-AR11/AR$9*100,0) -> 100 | CB11: =CB$7*EXP(-$AM11/CB$8) -> 209 | CC11: =(BZ11-CB11)^2 -> 11881 | CD11: =MAX(100-AT11/AT$9*100,0) -> 99.5671 | CE11: =MAX(100-AU11/AU$9*100,0) -> 100 | CF11: =CF$7*EXP(-$AM11/CF$8) -> 209 | CG11: =(CD11-CF11)^2 -> 11975.56 | CH11: =$AM11 -> 0 | CI11: =MAX(100-AW11/AW$9*100,0) -> 100 | CJ11: =MAX(100-AX11/AX$9*100,0) -> 100 | CK11: =CK$7*EXP(-$AM11/CK$8) -> 178 | CL11: =(CI11-CK11)^2 -> 6084 | CM11: =MAX(100-AZ11/AZ$9*100,0) -> 100 | CN11: =MAX(100-BA11/BA$9*100,0) -> 100 | CO11: =CO$7*EXP(-$AM11/CO$8) -> 133 | CP11: =(CM11-CO11)^2 -> 1089 | CQ11: =$AM11 -> 0 | CR11: =MAX(100-BC11/BC$9*100,0) -> 100 | CS11: =MAX(100-BD11/BD$9*100,0) -> 100 | CT11: =CT$7*EXP(-$AM11/CT$8) -> 147 | CU11: =(CR11-CT11)^2 -> 2209 | CV11: =MAX(100-BF11/BF$9*100,0) -> 99.497487 | CW11: =MAX(100-BG11/BG$9*100,0) -> 100 | CX11: =CX$7*EXP(-$AM11/CX$8) -> 134.8 | CY11: =(CV11-CX11)^2 -> 1246.2674 | CZ11: =$AM11 -> 0 | DA11: =MAX(100-BI11/BI$9*100,0) -> 100 | DB11: =MAX(100-BJ11/BJ$9*100,0) -> 100 | DC11: =DC$7*EXP(-$AM11/DC$8) -> 160 | DD11: =(DA11-DC11)^2 -> 3600 | DE11: =MAX(100-BL11/BL$9*100,0) -> 100 | DF11: =MAX(100-BM11/BM$9*100,0) -> 100 | DG11: =DG$7*EXP(-$AM11/DG$8) -> 120.5 | DH11: =(DE11-DG11)^2 -> 420.25 | DI11: =$AM11 -> 0 | DJ11: =MAX(100-BO11/BO$9*100,0) -> 100 | DK11: =MAX(100-BP11/BP$9*100,0) -> 100 | DL11: =DL$7*EXP(-$AM11/DL$8) -> 150 | DM11: =(DJ11-DL11)^2 -> 2500 | DN11: =MAX(100-BR11/BR$9*100,0) -> 100 | DO11: =MAX(100-BS11/BS$9*100,0) -> 100 | DP11: =DP$7*EXP(-$AM11/DP$8) -> 122 | DQ11: =(DN11-DP11)^2 -> 484 | DS11: =$AM11 -> 0 | DT11: =CA11 -> 100 | DU11: =DU$7*EXP(-DS11/DU$8) -> 163 | DV11: =(DT11-DU11)^2 -> 3969 | DX11: =$AM11 -> 0 | DY11: =CM11 -> 100 | DZ11: =DZ$7*EXP(-DX11/DZ$8) -> 158 | EA11: =(DY11-DZ11)^2 -> 3364 | EC11: =$AM11 -> 0 | ED11: =CV11 -> 99.497487 | EE11: =EE$7*EXP(-EC11/EE$8) -> 142 | EF11: =(ED11-EE11)^2 -> 1806.4636 | EH11: =$AM11 -> 0 | EI11: =DE11 -> 100 | EJ11: =EJ$7*EXP(-EH11/EJ$8) -> 120 | EK11: =(EI11-EJ11)^2 -> 400 | EM11: =AM11 -> 0 | EN11: =DN11 -> 100 | EO11: =EO$7*EXP(-EM11/EO$8) -> 120 | EP11: =(EN11-EO11)^2 -> 400 | ER11: =$AM11 -> 0 | ES11: =BZ11 -> 100 | ET11: =ET$7*EXP(-ER11/ET$8) -> 183 | EU11: =(ES11-ET11)^2 -> 6889 | EW11: =$AM11 -> 0 | EX11: =CI11 -> 100 | EY11: =EY$7*EXP(-EW11/EY$8) -> 245 | EZ11: =(EX11-EY11)^2 -> 21025 | FB11: =$AM11 -> 0 | FC11: =CR11 -> 100 | FD11: =FD$7*EXP(-FB11/FD$8) -> 178 | FE11: =(FC11-FD11)^2 -> 6084 | FG11: =$AM11 -> 0 | FH11: =DA11 -> 100 | FI11: =FI$7*EXP(-FG11/FI$8) -> 186 | FJ11: =(FH11-FI11)^2 -> 7396 | FL11: =EM11 -> 0 | FM11: =DJ11 -> 100 | FN11: =FN$7*EXP(-FL11/FN$8) -> 170 | FO11: =(FM11-FN11)^2 -> 4900 | FQ11: =AM11 -> 0 | FR11: =AN11/AN$9*100 -> 0 | FS11: =AO11/AO$9*100 -> 0 | FT11: =AQ11/AQ$9*100 -> 0 | FU11: =AR11/AR$9*100 -> 0 | FV11: =AT11/AT$9*100 -> 0.43290043 | FW11: =AU11/AU$9*100 -> 0 | FX11: =AW11/AW$9*100 -> 0 | FY11: =AX11/AX$9*100 -> 0 | FZ11: =AZ11/AZ$9*100 -> 0 | GA11: =BA11/BA$9*100 -> 0 | GB11: =BC11/BC$9*100 -> 0 | GC11: =BD11/BD$9*100 -> 0 | GD11: =BF11/BF$9*100 -> 0.50251256 | GE11: =BG11/BG$9*100 -> 0 | GF11: =BI11/BI$9*100 -> 0 | GG11: =BJ11/BJ$9*100 -> 0 | GH11: =BL11/BL$9*100 -> 0 | GI11: =BM11/BM$9*100 -> 0 | GJ11: =BO11/BO$9*100 -> 0 | GK11: =BP11/BP$9*100 -> 0 | GL11: =BR11/BR$9*100 -> 0 | GM11: =BS11/BS$9*100 -> 0 | GO11: =$AM11 -> 0 | GP11: =FT11 -> 0 | GQ11: =GQ$6*(1+GQ$5*(-1)^$FQ11)*EXP(-$FQ11/GQ$4) -> 205.19434 | GR11: =(GP11-GQ11)^2 -> 42104.717 | GS11: =EXP($FQ11/$JG$4)*GP11 -> 0 | GT11: =EXP($FQ11/$JG$4)*(-1)^$FQ11*GP11 -> 0 | GU11: =(-1)^GO11*GP11 -> 0 | GW11: =$AM11 -> 0 | GX11: =FX11 -> 0 | GY11: =GY$6*(1+GY$5*(-1)^$FQ11)*EXP(-$FQ11/GY$4) -> 205.19434 | GZ11: =(GX11-GY11)^2 -> 42104.717 | HA11: =EXP($FQ11/$JG$4)*GX11 -> 0 | HB11: =EXP($FQ11/$JG$4)*(-1)^$FQ11*GX11 -> 0 | HC11: =(-1)^GW11*GX11 -> 0 | HE11: =$AM11 -> 0 | HF11: =GB11 -> 0 | HG11: =HG$6*(1+HG$5*(-1)^$FQ11)*EXP(-$FQ11/HG$4) -> 205.19434 | HH11: =(HF11-HG11)^2 -> 42104.717 | HI11: =EXP($FQ11/$JG$4)*HF11 -> 0 | HJ11: =EXP($FQ11/$JG$4)*(-1)^$FQ11*HF11 -> 0 | HK11: =(-1)^HE11*HF11 -> 0 | HM11: =$AM11 -> 0 | HN11: =GF11 -> 0 | HO11: =HO$6*(1+HO$5*(-1)^$FQ11)*EXP(-$FQ11/HO$4) -> 165.21446 | HP11: =(HN11-HO11)^2 -> 27295.819 | HQ11: =EXP($FQ11/$JG$4)*HN11 -> 0 | HR11: =EXP($FQ11/$JG$4)*(-1)^$FQ11*HN11 -> 0 | HS11: =(-1)^HM11*HN11 -> 0 | HU11: =$AM11 -> 0 | HV11: =GJ11 -> 0 | HW11: =HW$6*(1+HW$5*(-1)^$FQ11)*EXP(-$FQ11/HW$4) -> 93.681025 | HX11: =(HV11-HW11)^2 -> 8776.1344 | HY11: =EXP($FQ11/$JG$4)*HV11 -> 0 | HZ11: =EXP($FQ11/$JG$4)*(-1)^$FQ11*HV11 -> 0 | IA11: =(-1)^HU11*HV11 -> 0 | IB11: 13.139509 | ID11: =$AM11 -> 0 | IE11: =FZ11 -> 0 | IF11: =IF$6*(1+IF$5*(-1)^$FQ11)*EXP(-$FQ11/IF$4) -> 55.134415 | IG11: =(IE11-IF11)^2 -> 3039.8037 | IH11: =EXP($FQ11/$JG$4)*IE11 -> 0 | II11: =EXP($FQ11/$JG$4)*(-1)^$FQ11*IE11 -> 0 | IJ11: =(-1)^ID11*IE11 -> 0 | IK11: 16.264621 | IM11: =$AM11 -> 0 | IN11: =GD11 -> 0.50251256 | IO11: =IO$6*(1+IO$5*(-1)^$FQ11)*EXP(-$FQ11/IO$4) -> 47.818041 | IP11: =(IN11-IO11)^2 -> 2238.7593 | IQ11: =EXP($FQ11/$JG$4)*IN11 -> 0.50251256 | IR11: =EXP($FQ11/$JG$4)*(-1)^$FQ11*IN11 -> 0.50251256 | IS11: =(-1)^IM11*IN11 -> 0.50251256 | IT11: 10.971789 | IV11: =$AM11 -> 0 | IW11: =GH11 -> 0 | IX11: =IX$6*(1+IX$5*(-1)^$FQ11)*EXP(-$FQ11/IX$4) -> 35.736006 | IY11: =(IW11-IX11)^2 -> 1277.0621 | IZ11: =EXP($FQ11/$JG$4)*IW11 -> 0 | JA11: =EXP($FQ11/$JG$4)*(-1)^$FQ11*IW11 -> 0 | JB11: =(-1)^IV11*IW11 -> 0 | JC11: 2.305836 | JE11: =$AM11 -> 0 | JF11: =GL11 -> 0 | JG11: =JG$6*(1+JG$5*(-1)^$FQ11)*EXP(-$FQ11/JG$4) -> 49.932502 | JH11: =(JF11-JG11)^2 -> 2493.2547 | JI11: =EXP($FQ11/$JG$4)*JF11 -> 0 | JJ11: =EXP($FQ11/$JG$4)*(-1)^$FQ11*JF11 -> 0 | JK11: =(-1)^JE11*JF11 -> 0 | JL11: 1.403096 | JO11: =$AM11 -> 0 | JP11: =GM11 -> 0 | JQ11: =JQ$6*(1+JQ$5*(-1)^$FQ11)*EXP(-$FQ11/JQ$4) -> 14.383243 | JR11: =(JP11-JQ11)^2 -> 206.87768 | JS11: =EXP($FQ11/$JG$4)*JP11 -> 0 | JT11: =EXP($FQ11/$JG$4)*(-1)^$FQ11*JP11 -> 0 | JU11: =(-1)^JO11*JP11 -> 0
A12: 2 | B12: 2 | C12: =B12-A12 -> 0 | D12: 2 | E12: 2 | F12: =E12-D12 -> 0 | G12: 1 | H12: 1 | I12: =H12-G12 -> 0 | J12: 2 | K12: 2 | L12: =K12-J12 -> 0 | M12: 3 | N12: 5 | O12: =N12-M12 -> 2 | P12: 1 | Q12: 1 | R12: =Q12-P12 -> 0 | S12: 2 | T12: 2 | U12: =T12-S12 -> 0 | V12: 3 | W12: 5 | X12: =W12-V12 -> 2 | Y12: 6 | Z12: 8 | AA12: =Z12-Y12 -> 2 | AB12: 4 | AC12: 10 | AD12: =AC12-AB12 -> 6 | AE12: 7 | AF12: 14 | AG12: =AF12-AE12 -> 7 | AI12: BB | AJ12: =COUNTIFS(H$2:H$1000,2,G$2:G$1000,2) -> 93 | AM12: 1 | AN12: 56 | AO12: 56 | AP12: 0 | AQ12: 71 | AR12: 64 | AS12: 5 | AT12: 90 | AU12: 79 | AV12: 26 | AW12: 32 | AX12: 21 | AY12: 16 | AZ12: 38 | BA12: 18 | BB12: 28 | BC12: 51 | BD12: 24 | BE12: 29 | BF12: 24 | BG12: 10 | BH12: 7 | BI12: 27 | BJ12: 11 | BK12: 28 | BL12: 11 | BM12: 3 | BN12: 4 | BO12: 37 | BP12: 10 | BQ12: 12 | BR12: 13 | BS12: 3 | BT12: 2 | BW12: =$AM12 -> 1 | BX12: =MAX(BX11-AN12/AN$9*100,0) -> 51.304348 | BY12: =MAX(BY11-AO12/AO$9*100,0) -> 51.304348 | BZ12: =MAX(BZ11-AQ12/AQ$9*100,0) -> 59.428571 | CA12: =MAX(CA11-AR12/AR$9*100,0) -> 63.428571 | CB12: =CB$7*EXP(-$AM12/CB$8) -> 57.033166 | CC12: =(BZ12-CB12)^2 -> 5.7379685 | CD12: =MAX(CD11-AT12/AT$9*100,0) -> 60.606061 | CE12: =MAX(CE11-AU12/AU$9*100,0) -> 65.800866 | CF12: =CF$7*EXP(-$AM12/CF$8) -> 58.939498 | CG12: =(CD12-CF12)^2 -> 2.7774295 | CH12: =$AM12 -> 1 | CI12: =MAX(CI11-AW12/AW$9*100,0) -> 76.470588 | CJ12: =MAX(CJ11-AX12/AX$9*100,0) -> 84.558824 | CK12: =CK$7*EXP(-$AM12/CK$8) -> 75.723057 | CL12: =(CI12-CK12)^2 -> 0.55880321 | CM12: =MAX(CM11-AZ12/AZ$9*100,0) -> 80.71066 | CN12: =MAX(CN11-BA12/BA$9*100,0) -> 90.862944 | CO12: =CO$7*EXP(-$AM12/CO$8) -> 82.234909 | CP12: =(CM12-CO12)^2 -> 2.3233358 | CQ12: =$AM12 -> 1 | CR12: =MAX(CR11-BC12/BC$9*100,0) -> 67.924528 | CS12: =MAX(CS11-BD12/BD$9*100,0) -> 84.90566 | CT12: =CT$7*EXP(-$AM12/CT$8) -> 66.888765 | CU12: =(CR12-CT12)^2 -> 1.0728061 | CV12: =MAX(CV11-BF12/BF$9*100,0) -> 87.437186 | CW12: =MAX(CW11-BG12/BG$9*100,0) -> 94.974874 | CX12: =CX$7*EXP(-$AM12/CX$8) -> 89.172176 | CY12: =(CV12-CX12)^2 -> 3.0101891 | CZ12: =$AM12 -> 1 | DA12: =MAX(DA11-BI12/BI$9*100,0) -> 81.506849 | DB12: =MAX(DB11-BJ12/BJ$9*100,0) -> 92.465753 | DC12: =DC$7*EXP(-$AM12/DC$8) -> 77.111067 | DD12: =(DA12-DC12)^2 -> 19.322904 | DE12: =MAX(DE11-BL12/BL$9*100,0) -> 92.993631 | DF12: =MAX(DF11-BM12/BM$9*100,0) -> 98.089172 | DG12: =DG$7*EXP(-$AM12/DG$8) -> 93.845494 | DH12: =(DE12-DG12)^2 -> 0.72567191 | DI12: =$AM12 -> 1 | DJ12: =MAX(DJ11-BO12/BO$9*100,0) -> 81.025641 | DK12: =MAX(DK11-BP12/BP$9*100,0) -> 94.871795 | DL12: =DL$7*EXP(-$AM12/DL$8) -> 81.218119 | DM12: =(DJ12-DL12)^2 -> 0.037047737 | DN12: =MAX(DN11-BR12/BR$9*100,0) -> 93.467337 | DO12: =MAX(DO11-BS12/BS$9*100,0) -> 98.492462 | DP12: =DP$7*EXP(-$AM12/DP$8) -> 91.903115 | DQ12: =(DN12-DP12)^2 -> 2.4467891 | DS12: =$AM12 -> 1 | DT12: =CA12 -> 63.428571 | DU12: =DU$7*EXP(-DS12/DU$8) -> 58.138167 | DV12: =(DT12-DU12)^2 -> 27.98838 | DX12: =$AM12 -> 1 | DY12: =CM12 -> 80.71066 | DZ12: =DZ$7*EXP(-DX12/DZ$8) -> 90.088929 | EA12: =(DY12-DZ12)^2 -> 87.951928 | EC12: =$AM12 -> 1 | ED12: =CV12 -> 87.437186 | EE12: =EE$7*EXP(-EC12/EE$8) -> 91.757189 | EF12: =(ED12-EE12)^2 -> 18.662424 | EH12: =$AM12 -> 1 | EI12: =DE12 -> 92.993631 | EJ12: =EJ$7*EXP(-EH12/EJ$8) -> 93.456094 | EK12: =(EI12-EJ12)^2 -> 0.21387239 | EM12: =AM12 -> 1 | EN12: =DN12 -> 93.467337 | EO12: =EO$7*EXP(-EM12/EO$8) -> 91.242349 | EP12: =(EN12-EO12)^2 -> 4.9505711 | ER12: =$AM12 -> 1 | ES12: =BZ12 -> 59.428571 | ET12: =ET$7*EXP(-ER12/ET$8) -> 55.645987 | EU12: =(ES12-ET12)^2 -> 14.307946 | EW12: =$AM12 -> 1 | EX12: =CI12 -> 76.470588 | EY12: =EY$7*EXP(-EW12/EY$8) -> 81.643084 | EZ12: =(EX12-EY12)^2 -> 26.754711 | FB12: =$AM12 -> 1 | FC12: =CR12 -> 67.924528 | FD12: =FD$7*EXP(-FB12/FD$8) -> 68.676193 | FE12: =(FC12-FD12)^2 -> 0.56499924 | FG12: =$AM12 -> 1 | FH12: =DA12 -> 81.506849 | FI12: =FI$7*EXP(-FG12/FI$8) -> 81.393905 | FJ12: =(FH12-FI12)^2 -> 0.012756424 | FL12: =EM12 -> 1 | FM12: =DJ12 -> 81.025641 | FN12: =FN$7*EXP(-FL12/FN$8) -> 87.28091 | FO12: =(FM12-FN12)^2 -> 39.128393 | FQ12: =AM12 -> 1 | FR12: =AN12/AN$9*100 -> 48.695652 | FS12: =AO12/AO$9*100 -> 48.695652 | FT12: =AQ12/AQ$9*100 -> 40.571429 | FU12: =AR12/AR$9*100 -> 36.571429 | FV12: =AT12/AT$9*100 -> 38.961039 | FW12: =AU12/AU$9*100 -> 34.199134 | FX12: =AW12/AW$9*100 -> 23.529412 | FY12: =AX12/AX$9*100 -> 15.441176 | FZ12: =AZ12/AZ$9*100 -> 19.28934 | GA12: =BA12/BA$9*100 -> 9.1370558 | GB12: =BC12/BC$9*100 -> 32.075472 | GC12: =BD12/BD$9*100 -> 15.09434 | GD12: =BF12/BF$9*100 -> 12.060302 | GE12: =BG12/BG$9*100 -> 5.0251256 | GF12: =BI12/BI$9*100 -> 18.493151 | GG12: =BJ12/BJ$9*100 -> 7.5342466 | GH12: =BL12/BL$9*100 -> 7.0063694 | GI12: =BM12/BM$9*100 -> 1.910828 | GJ12: =BO12/BO$9*100 -> 18.974359 | GK12: =BP12/BP$9*100 -> 5.1282051 | GL12: =BR12/BR$9*100 -> 6.5326633 | GM12: =BS12/BS$9*100 -> 1.5075377 | GO12: =$AM12 -> 1 | GP12: =FT12 -> 40.571429 | GQ12: =GQ$6*(1+GQ$5*(-1)^$FQ12)*EXP(-$FQ12/GQ$4) -> 32.92595 | GR12: =(GP12-GQ12)^2 -> 58.453346 | GS12: =EXP($FQ12/$JG$4)*GP12 -> 51.249658 | GT12: =EXP($FQ12/$JG$4)*(-1)^$FQ12*GP12 -> -51.249658 | GU12: =(-1)^GO12*GP12 -> -40.571429 | GW12: =$AM12 -> 1 | GX12: =FX12 -> 23.529412 | GY12: =GY$6*(1+GY$5*(-1)^$FQ12)*EXP(-$FQ12/GY$4) -> 32.92595 | GZ12: =(GX12-GY12)^2 -> 88.294927 | HA12: =EXP($FQ12/$JG$4)*GX12 -> 29.722254 | HB12: =EXP($FQ12/$JG$4)*(-1)^$FQ12*GX12 -> -29.722254 | HC12: =(-1)^GW12*GX12 -> -23.529412 | HE12: =$AM12 -> 1 | HF12: =GB12 -> 32.075472 | HG12: =HG$6*(1+HG$5*(-1)^$FQ12)*EXP(-$FQ12/HG$4) -> 32.92595 | HH12: =(HF12-HG12)^2 -> 0.72331301 | HI12: =EXP($FQ12/$JG$4)*HF12 -> 40.517601 | HJ12: =EXP($FQ12/$JG$4)*(-1)^$FQ12*HF12 -> -40.517601 | HK12: =(-1)^HE12*HF12 -> -32.075472 | HM12: =$AM12 -> 1 | HN12: =GF12 -> 18.493151 | HO12: =HO$6*(1+HO$5*(-1)^$FQ12)*EXP(-$FQ12/HO$4) -> 19.927377 | HP12: =(HN12-HO12)^2 -> 2.0570059 | HQ12: =EXP($FQ12/$JG$4)*HN12 -> 23.36047 | HR12: =EXP($FQ12/$JG$4)*(-1)^$FQ12*HN12 -> -23.36047 | HS12: =(-1)^HM12*HN12 -> -18.493151 | HU12: =$AM12 -> 1 | HV12: =GJ12 -> 18.974359 | HW12: =HW$6*(1+HW$5*(-1)^$FQ12)*EXP(-$FQ12/HW$4) -> 20.061559 | HX12: =(HV12-HW12)^2 -> 1.1820038 | HY12: =EXP($FQ12/$JG$4)*HV12 -> 23.968331 | HZ12: =EXP($FQ12/$JG$4)*(-1)^$FQ12*HV12 -> -23.968331 | IA12: =(-1)^HU12*HV12 -> -18.974359 | IB12: 46.099695 | ID12: =$AM12 -> 1 | IE12: =FZ12 -> 19.28934 | IF12: =IF$6*(1+IF$5*(-1)^$FQ12)*EXP(-$FQ12/IF$4) -> 20.351336 | IG12: =(IE12-IF12)^2 -> 1.127835 | IH12: =EXP($FQ12/$JG$4)*IE12 -> 24.366213 | II12: =EXP($FQ12/$JG$4)*(-1)^$FQ12*IE12 -> -24.366213 | IJ12: =(-1)^ID12*IE12 -> -19.28934 | IK12: 32.733654 | IM12: =$AM12 -> 1 | IN12: =GD12 -> 12.060302 | IO12: =IO$6*(1+IO$5*(-1)^$FQ12)*EXP(-$FQ12/IO$4) -> 16.524473 | IP12: =(IN12-IO12)^2 -> 19.92883 | IQ12: =EXP($FQ12/$JG$4)*IN12 -> 15.234522 | IR12: =EXP($FQ12/$JG$4)*(-1)^$FQ12*IN12 -> -15.234522 | IS12: =(-1)^IM12*IN12 -> -12.060302 | IT12: 31.128394 | IV12: =$AM12 -> 1 | IW12: =GH12 -> 7.0063694 | IX12: =IX$6*(1+IX$5*(-1)^$FQ12)*EXP(-$FQ12/IX$4) -> 7.6028177 | IY12: =(IW12-IX12)^2 -> 0.35575055 | IZ12: =EXP($FQ12/$JG$4)*IW12 -> 8.8504164 | JA12: =EXP($FQ12/$JG$4)*(-1)^$FQ12*IW12 -> -8.8504164 | JB12: =(-1)^IV12*IW12 -> -7.0063694 | JC12: 25.105008 | JE12: =$AM12 -> 1 | JF12: =GL12 -> 6.5326633 | JG12: =JG$6*(1+JG$5*(-1)^$FQ12)*EXP(-$FQ12/JG$4) -> 6.0375265 | JH12: =(JF12-JG12)^2 -> 0.2451605 | JI12: =EXP($FQ12/$JG$4)*JF12 -> 8.2520329 | JJ12: =EXP($FQ12/$JG$4)*(-1)^$FQ12*JF12 -> -8.2520329 | JK12: =(-1)^JE12*JF12 -> -6.5326633 | JL12: 29.19511 | JO12: =$AM12 -> 1 | JP12: =GM12 -> 1.5075377 | JQ12: =JQ$6*(1+JQ$5*(-1)^$FQ12)*EXP(-$FQ12/JQ$4) -> 2.5290299 | JR12: =(JP12-JQ12)^2 -> 1.0434463 | JS12: =EXP($FQ12/$JG$4)*JP12 -> 1.9043153 | JT12: =EXP($FQ12/$JG$4)*(-1)^$FQ12*JP12 -> -1.9043153 | JU12: =(-1)^JO12*JP12 -> -1.5075377
A13: 1 | B13: 1 | C13: =B13-A13 -> 0 | D13: 1 | E13: 1 | F13: =E13-D13 -> 0 | G13: 1 | H13: 1 | I13: =H13-G13 -> 0 | J13: 3 | K13: 5 | L13: =K13-J13 -> 2 | M13: 1 | N13: 1 | O13: =N13-M13 -> 0 | P13: 2 | Q13: 2 | R13: =Q13-P13 -> 0 | S13: 2 | T13: 2 | U13: =T13-S13 -> 0 | V13: 4 | W13: 8 | X13: =W13-V13 -> 4 | Y13: 4 | Z13: 8 | AA13: =Z13-Y13 -> 4 | AB13: 2 | AC13: 2 | AD13: =AC13-AB13 -> 0 | AE13: 6 | AF13: 10 | AG13: =AF13-AE13 -> 4 | AI13: BS | AJ13: =COUNTIFS(H$2:H$1000,2,G$2:G$1000,1) -> 11 | AM13: 2 | AN13: 57 | AO13: 57 | AP13: 0 | AQ13: 83 | AR13: 84 | AS13: 5 | AT13: 105 | AU13: 104 | AV13: 1 | AW13: 64 | AX13: 55 | AY13: 21 | AZ13: 52 | BA13: 47 | BB13: 30 | BC13: 66 | BD13: 51 | BE13: 42 | BF13: 53 | BG13: 27 | BH13: 43 | BI13: 73 | BJ13: 39 | BK13: 40 | BL13: 35 | BM13: 8 | BN13: 21 | BO13: 76 | BP13: 23 | BQ13: 71 | BR13: 59 | BS13: 17 | BT13: 30 | BW13: =$AM13 -> 2 | BX13: =MAX(BX12-AN13/AN$9*100,0) -> 1.7391304 | BY13: =MAX(BY12-AO13/AO$9*100,0) -> 1.7391304 | BZ13: =MAX(BZ12-AQ13/AQ$9*100,0) -> 12 | CA13: =MAX(CA12-AR13/AR$9*100,0) -> 15.428571 | CB13: =CB$7*EXP(-$AM13/CB$8) -> 15.56355 | CC13: =(BZ13-CB13)^2 -> 12.69889 | CD13: =MAX(CD12-AT13/AT$9*100,0) -> 15.151515 | CE13: =MAX(CE12-AU13/AU$9*100,0) -> 20.779221 | CF13: =CF$7*EXP(-$AM13/CF$8) -> 16.621361 | CG13: =(CD13-CF13)^2 -> 2.1604472 | CH13: =$AM13 -> 2 | CI13: =MAX(CI12-AW13/AW$9*100,0) -> 29.411765 | CJ13: =MAX(CJ12-AX13/AX$9*100,0) -> 44.117647 | CK13: =CK$7*EXP(-$AM13/CK$8) -> 32.213378 | CL13: =(CI13-CK13)^2 -> 7.8490386 | CM13: =MAX(CM12-AZ13/AZ$9*100,0) -> 54.314721 | CN13: =MAX(CN12-BA13/BA$9*100,0) -> 67.005076 | CO13: =CO$7*EXP(-$AM13/CO$8) -> 50.846468 | CP13: =(CM13-CO13)^2 -> 12.028776 | CQ13: =$AM13 -> 2 | CR13: =MAX(CR12-BC13/BC$9*100,0) -> 26.415094 | CS13: =MAX(CS12-BD13/BD$9*100,0) -> 52.830189 | CT13: =CT$7*EXP(-$AM13/CT$8) -> 30.436101 | CU13: =(CR13-CT13)^2 -> 16.168495 | CV13: =MAX(CV12-BF13/BF$9*100,0) -> 60.80402 | CW13: =MAX(CW12-BG13/BG$9*100,0) -> 81.407035 | CX13: =CX$7*EXP(-$AM13/CX$8) -> 58.988701 | CY13: =(CV13-CX13)^2 -> 3.2953834 | CZ13: =$AM13 -> 2 | DA13: =MAX(DA12-BI13/BI$9*100,0) -> 31.506849 | DB13: =MAX(DB12-BJ13/BJ$9*100,0) -> 65.753425 | DC13: =DC$7*EXP(-$AM13/DC$8) -> 37.163229 | DD13: =(DA13-DC13)^2 -> 31.994629 | DE13: =MAX(DE12-BL13/BL$9*100,0) -> 70.700637 | DF13: =MAX(DF12-BM13/BM$9*100,0) -> 92.993631 | DG13: =DG$7*EXP(-$AM13/DG$8) -> 73.086944 | DH13: =(DE13-DG13)^2 -> 5.6944637 | DI13: =$AM13 -> 2 | DJ13: =MAX(DJ12-BO13/BO$9*100,0) -> 42.051282 | DK13: =MAX(DK12-BP13/BP$9*100,0) -> 83.076923 | DL13: =DL$7*EXP(-$AM13/DL$8) -> 43.975886 | DM13: =(DJ13-DL13)^2 -> 3.7040988 | DN13: =MAX(DN12-BR13/BR$9*100,0) -> 63.819095 | DO13: =MAX(DO12-BS13/BS$9*100,0) -> 89.949749 | DP13: =DP$7*EXP(-$AM13/DP$8) -> 69.231005 | DQ13: =(DN13-DP13)^2 -> 29.288761 | DS13: =$AM13 -> 2 | DT13: =CA13 -> 15.428571 | DU13: =DU$7*EXP(-DS13/DU$8) -> 20.736481 | DV13: =(DT13-DU13)^2 -> 28.173907 | DX13: =$AM13 -> 2 | DY13: =CM13 -> 54.314721 | DZ13: =DZ$7*EXP(-DX13/DZ$8) -> 51.367184 | EA13: =(DY13-DZ13)^2 -> 8.6879725 | EC13: =$AM13 -> 2 | ED13: =CV13 -> 60.80402 | EE13: =EE$7*EXP(-EC13/EE$8) -> 59.29142 | EF13: =(ED13-EE13)^2 -> 2.2879582 | EH13: =$AM13 -> 2 | EI13: =DE13 -> 70.700637 | EJ13: =EJ$7*EXP(-EH13/EJ$8) -> 72.783679 | EK13: =(EI13-EJ13)^2 -> 4.3390649 | EM13: =AM13 -> 2 | EN13: =DN13 -> 63.819095 | EO13: =EO$7*EXP(-EM13/EO$8) -> 69.376385 | EP13: =(EN13-EO13)^2 -> 30.883468 | ER13: =$AM13 -> 2 | ES13: =BZ13 -> 12 | ET13: =ET$7*EXP(-ER13/ET$8) -> 16.920633 | EU13: =(ES13-ET13)^2 -> 24.21263 | EW13: =$AM13 -> 2 | EX13: =CI13 -> 29.411765 | EY13: =EY$7*EXP(-EW13/EY$8) -> 27.206503 | EZ13: =(EX13-EY13)^2 -> 4.8631807 | FB13: =$AM13 -> 2 | FC13: =CR13 -> 26.415094 | FD13: =FD$7*EXP(-FB13/FD$8) -> 26.496738 | FE13: =(FC13-FD13)^2 -> 0.0066657498 | FG13: =$AM13 -> 2 | FH13: =DA13 -> 31.506849 | FI13: =FI$7*EXP(-FG13/FI$8) -> 35.618106 | FJ13: =(FH13-FI13)^2 -> 16.902434 | FL13: =EM13 -> 2 | FM13: =DJ13 -> 42.051282 | FN13: =FN$7*EXP(-FL13/FN$8) -> 44.811513 | FO13: =(FM13-FN13)^2 -> 7.6188775 | FQ13: =AM13 -> 2 | FR13: =AN13/AN$9*100 -> 49.565217 | FS13: =AO13/AO$9*100 -> 49.565217 | FT13: =AQ13/AQ$9*100 -> 47.428571 | FU13: =AR13/AR$9*100 -> 48 | FV13: =AT13/AT$9*100 -> 45.454545 | FW13: =AU13/AU$9*100 -> 45.021645 | FX13: =AW13/AW$9*100 -> 47.058824 | FY13: =AX13/AX$9*100 -> 40.441176 | FZ13: =AZ13/AZ$9*100 -> 26.395939 | GA13: =BA13/BA$9*100 -> 23.857868 | GB13: =BC13/BC$9*100 -> 41.509434 | GC13: =BD13/BD$9*100 -> 32.075472 | GD13: =BF13/BF$9*100 -> 26.633166 | GE13: =BG13/BG$9*100 -> 13.567839 | GF13: =BI13/BI$9*100 -> 50 | GG13: =BJ13/BJ$9*100 -> 26.712329 | GH13: =BL13/BL$9*100 -> 22.292994 | GI13: =BM13/BM$9*100 -> 5.0955414 | GJ13: =BO13/BO$9*100 -> 38.974359 | GK13: =BP13/BP$9*100 -> 11.794872 | GL13: =BR13/BR$9*100 -> 29.648241 | GM13: =BS13/BS$9*100 -> 8.5427136 | GO13: =$AM13 -> 2 | GP13: =FT13 -> 47.428571 | GQ13: =GQ$6*(1+GQ$5*(-1)^$FQ13)*EXP(-$FQ13/GQ$4) -> 45.096562 | GR13: =(GP13-GQ13)^2 -> 5.4382685 | GS13: =EXP($FQ13/$JG$4)*GP13 -> 75.680047 | GT13: =EXP($FQ13/$JG$4)*(-1)^$FQ13*GP13 -> 75.680047 | GU13: =(-1)^GO13*GP13 -> 47.428571 | GW13: =$AM13 -> 2 | GX13: =FX13 -> 47.058824 | GY13: =GY$6*(1+GY$5*(-1)^$FQ13)*EXP(-$FQ13/GY$4) -> 45.096562 | GZ13: =(GX13-GY13)^2 -> 3.8504708 | HA13: =EXP($FQ13/$JG$4)*GX13 -> 75.090053 | HB13: =EXP($FQ13/$JG$4)*(-1)^$FQ13*GX13 -> 75.090053 | HC13: =(-1)^GW13*GX13 -> 47.058824 | HE13: =$AM13 -> 2 | HF13: =GB13 -> 41.509434 | HG13: =HG$6*(1+HG$5*(-1)^$FQ13)*EXP(-$FQ13/HG$4) -> 45.096562 | HH13: =(HF13-HG13)^2 -> 12.867487 | HI13: =EXP($FQ13/$JG$4)*HF13 -> 66.235094 | HJ13: =EXP($FQ13/$JG$4)*(-1)^$FQ13*HF13 -> 66.235094 | HK13: =(-1)^HE13*HF13 -> 41.509434 | HM13: =$AM13 -> 2 | HN13: =GF13 -> 50 | HO13: =HO$6*(1+HO$5*(-1)^$FQ13)*EXP(-$FQ13/HO$4) -> 49.880973 | HP13: =(HN13-HO13)^2 -> 0.014167486 | HQ13: =EXP($FQ13/$JG$4)*HN13 -> 79.783182 | HR13: =EXP($FQ13/$JG$4)*(-1)^$FQ13*HN13 -> 79.783182 | HS13: =(-1)^HM13*HN13 -> 50 | HU13: =$AM13 -> 2 | HV13: =GJ13 -> 38.974359 | HW13: =HW$6*(1+HW$5*(-1)^$FQ13)*EXP(-$FQ13/HW$4) -> 38.665198 | HX13: =(HV13-HW13)^2 -> 0.095580809 | HY13: =EXP($FQ13/$JG$4)*HV13 -> 62.189967 | HZ13: =EXP($FQ13/$JG$4)*(-1)^$FQ13*HV13 -> 62.189967 | IA13: =(-1)^HU13*HV13 -> 38.974359 | IB13: 13.960867 | ID13: =$AM13 -> 2 | IE13: =FZ13 -> 26.395939 | IF13: =IF$6*(1+IF$5*(-1)^$FQ13)*EXP(-$FQ13/IF$4) -> 28.306952 | IG13: =(IE13-IF13)^2 -> 3.6519713 | IH13: =EXP($FQ13/$JG$4)*IE13 -> 42.11904 | II13: =EXP($FQ13/$JG$4)*(-1)^$FQ13*IE13 -> 42.11904 | IJ13: =(-1)^ID13*IE13 -> 26.395939 | IK13: 18.186517 | IM13: =$AM13 -> 2 | IN13: =GD13 -> 26.633166 | IO13: =IO$6*(1+IO$5*(-1)^$FQ13)*EXP(-$FQ13/IO$4) -> 27.003714 | IP13: =(IN13-IO13)^2 -> 0.13730628 | IQ13: =EXP($FQ13/$JG$4)*IN13 -> 42.497574 | IR13: =EXP($FQ13/$JG$4)*(-1)^$FQ13*IN13 -> 42.497574 | IS13: =(-1)^IM13*IN13 -> 26.633166 | IT13: 16.151638 | IV13: =$AM13 -> 2 | IW13: =GH13 -> 22.292994 | IX13: =IX$6*(1+IX$5*(-1)^$FQ13)*EXP(-$FQ13/IX$4) -> 24.325942 | IY13: =(IW13-IX13)^2 -> 4.132881 | IZ13: =EXP($FQ13/$JG$4)*IW13 -> 35.572119 | JA13: =EXP($FQ13/$JG$4)*(-1)^$FQ13*IW13 -> 35.572119 | JB13: =(-1)^IV13*IW13 -> 22.292994 | JC13: 5.346802 | JE13: =$AM13 -> 2 | JF13: =GL13 -> 29.648241 | JG13: =JG$6*(1+JG$5*(-1)^$FQ13)*EXP(-$FQ13/JG$4) -> 31.292624 | JH13: =(JF13-JG13)^2 -> 2.7039942 | JI13: =EXP($FQ13/$JG$4)*JF13 -> 47.30862 | JJ13: =EXP($FQ13/$JG$4)*(-1)^$FQ13*JF13 -> 47.30862 | JK13: =(-1)^JE13*JF13 -> 29.648241 | JL13: 3.455387 | JO13: =$AM13 -> 2 | JP13: =GM13 -> 8.5427136 | JQ13: =JQ$6*(1+JQ$5*(-1)^$FQ13)*EXP(-$FQ13/JQ$4) -> 12.256591 | JR13: =(JP13-JQ13)^2 -> 13.792887 | JS13: =EXP($FQ13/$JG$4)*JP13 -> 13.631297 | JT13: =EXP($FQ13/$JG$4)*(-1)^$FQ13*JP13 -> 13.631297 | JU13: =(-1)^JO13*JP13 -> 8.5427136
A14: 1 | B14: 1 | C14: =B14-A14 -> 0 | D14: 1 | E14: 1 | F14: =E14-D14 -> 0 | G14: 1 | H14: 1 | I14: =H14-G14 -> 0 | J14: 4 | K14: 4 | L14: =K14-J14 -> 0 | M14: 1 | N14: 1 | O14: =N14-M14 -> 0 | P14: 1 | Q14: 2 | R14: =Q14-P14 -> 1 | S14: 3 | T14: 7 | U14: =T14-S14 -> 4 | V14: 2 | W14: 4 | X14: =W14-V14 -> 2 | Y14: 6 | Z14: 10 | AA14: =Z14-Y14 -> 4 | AB14: 4 | AC14: 8 | AD14: =AC14-AB14 -> 4 | AE14: 8 | AF14: 18 | AG14: =AF14-AE14 -> 10 | AI14: SS | AJ14: =COUNTIFS(H$2:H$1000,2,G$2:G$1000,0) -> 0 | AM14: 3 | AN14: 1 | AO14: 1 | AP14: 0 | AQ14: 16 | AR14: 20 | AS14: 0 | AT14: 27 | AU14: 38 | AV14: 0 | AW14: 12 | AX14: 18 | AY14: 2 | AZ14: 35 | BA14: 37 | BB14: 6 | BC14: 15 | BD14: 24 | BE14: 6 | BF14: 34 | BG14: 14 | BH14: 24 | BI14: 14 | BJ14: 23 | BK14: 13 | BL14: 12 | BM14: 7 | BN14: 15 | BO14: 25 | BP14: 35 | BQ14: 26 | BR14: 9 | BS14: 5 | BT14: 9 | BW14: =$AM14 -> 3 | BX14: =MAX(BX13-AN14/AN$9*100,0) -> 0.86956522 | BY14: =MAX(BY13-AO14/AO$9*100,0) -> 0.86956522 | BZ14: =MAX(BZ13-AQ14/AQ$9*100,0) -> 2.8571429 | CA14: =MAX(CA13-AR14/AR$9*100,0) -> 4 | CB14: =CB$7*EXP(-$AM14/CB$8) -> 4.2470743 | CC14: =(BZ14-CB14)^2 -> 1.9319095 | CD14: =MAX(CD13-AT14/AT$9*100,0) -> 3.4632035 | CE14: =MAX(CE13-AU14/AU$9*100,0) -> 4.3290043 | CF14: =CF$7*EXP(-$AM14/CF$8) -> 4.687343 | CG14: =(CD14-CF14)^2 -> 1.4985176 | CH14: =$AM14 -> 3 | CI14: =MAX(CI13-AW14/AW$9*100,0) -> 20.588235 | CJ14: =MAX(CJ13-AX14/AX$9*100,0) -> 30.882353 | CK14: =CK$7*EXP(-$AM14/CK$8) -> 13.703907 | CL14: =(CI14-CK14)^2 -> 47.393974 | CM14: =MAX(CM13-AZ14/AZ$9*100,0) -> 36.548223 | CN14: =MAX(CN13-BA14/BA$9*100,0) -> 48.22335 | CO14: =CO$7*EXP(-$AM14/CO$8) -> 31.438757 | CP14: =(CM14-CO14)^2 -> 26.106645 | CQ14: =$AM14 -> 3 | CR14: =MAX(CR13-BC14/BC$9*100,0) -> 16.981132 | CS14: =MAX(CS13-BD14/BD$9*100,0) -> 37.735849 | CT14: =CT$7*EXP(-$AM14/CT$8) -> 13.849205 | CU14: =(CR14-CT14)^2 -> 9.8089644 | CV14: =MAX(CV13-BF14/BF$9*100,0) -> 43.718593 | CW14: =MAX(CW13-BG14/BG$9*100,0) -> 74.371859 | CX14: =CX$7*EXP(-$AM14/CX$8) -> 39.02189 | CY14: =(CV14-CX14)^2 -> 22.059016 | CZ14: =$AM14 -> 3 | DA14: =MAX(DA13-BI14/BI$9*100,0) -> 21.917808 | DB14: =MAX(DB13-BJ14/BJ$9*100,0) -> 50 | DC14: =DC$7*EXP(-$AM14/DC$8) -> 17.910601 | DD14: =(DA14-DC14)^2 -> 16.057707 | DE14: =MAX(DE13-BL14/BL$9*100,0) -> 63.057325 | DF14: =MAX(DF13-BM14/BM$9*100,0) -> 88.535032 | DG14: =DG$7*EXP(-$AM14/DG$8) -> 56.92017 | DH14: =(DE14-DG14)^2 -> 37.664674 | DI14: =$AM14 -> 3 | DJ14: =MAX(DJ13-BO14/BO$9*100,0) -> 29.230769 | DK14: =MAX(DK13-BP14/BP$9*100,0) -> 65.128205 | DL14: =DL$7*EXP(-$AM14/DL$8) -> 23.810925 | DM14: =(DJ14-DL14)^2 -> 29.374715 | DN14: =MAX(DN13-BR14/BR$9*100,0) -> 59.296482 | DO14: =MAX(DO13-BS14/BS$9*100,0) -> 87.437186 | DP14: =DP$7*EXP(-$AM14/DP$8) -> 52.152008 | DQ14: =(DN14-DP14)^2 -> 51.043513 | DS14: =$AM14 -> 3 | DT14: =CA14 -> 4 | DU14: =DU$7*EXP(-DS14/DU$8) -> 7.3962025 | DV14: =(DT14-DU14)^2 -> 11.534192 | DX14: =$AM14 -> 3 | DY14: =CM14 -> 36.548223 | DZ14: =DZ$7*EXP(-DX14/DZ$8) -> 29.2887 | EA14: =(DY14-DZ14)^2 -> 52.70068 | EC14: =$AM14 -> 3 | ED14: =CV14 -> 43.718593 | EE14: =EE$7*EXP(-EC14/EE$8) -> 38.312775 | EF14: =(ED14-EE14)^2 -> 29.222869 | EH14: =$AM14 -> 3 | EI14: =DE14 -> 63.057325 | EJ14: =EJ$7*EXP(-EH14/EJ$8) -> 56.683986 | EK14: =(EI14-EJ14)^2 -> 40.619444 | EM14: =AM14 -> 3 | EN14: =DN14 -> 59.296482 | EO14: =EO$7*EXP(-EM14/EO$8) -> 52.750536 | EP14: =(EN14-EO14)^2 -> 42.849414 | ER14: =$AM14 -> 3 | ES14: =BZ14 -> 2.8571429 | ET14: =ET$7*EXP(-ER14/ET$8) -> 5.1451657 | EU14: =(ES14-ET14)^2 -> 5.2350487 | EW14: =$AM14 -> 3 | EX14: =CI14 -> 20.588235 | EY14: =EY$7*EXP(-EW14/EY$8) -> 9.0662154 | EZ14: =(EX14-EY14)^2 -> 132.75694 | FB14: =$AM14 -> 3 | FC14: =CR14 -> 16.981132 | FD14: =FD$7*EXP(-FB14/FD$8) -> 10.223006 | FE14: =(FC14-FD14)^2 -> 45.672265 | FG14: =$AM14 -> 3 | FH14: =DA14 -> 21.917808 | FI14: =FI$7*EXP(-FG14/FI$8) -> 15.586542 | FJ14: =(FH14-FI14)^2 -> 40.084936 | FL14: =EM14 -> 3 | FM14: =DJ14 -> 29.230769 | FN14: =FN$7*EXP(-FL14/FN$8) -> 23.006998 | FO14: =(FM14-FN14)^2 -> 38.735326 | FQ14: =AM14 -> 3 | FR14: =AN14/AN$9*100 -> 0.86956522 | FS14: =AO14/AO$9*100 -> 0.86956522 | FT14: =AQ14/AQ$9*100 -> 9.1428571 | FU14: =AR14/AR$9*100 -> 11.428571 | FV14: =AT14/AT$9*100 -> 11.688312 | FW14: =AU14/AU$9*100 -> 16.450216 | FX14: =AW14/AW$9*100 -> 8.8235294 | FY14: =AX14/AX$9*100 -> 13.235294 | FZ14: =AZ14/AZ$9*100 -> 17.766497 | GA14: =BA14/BA$9*100 -> 18.781726 | GB14: =BC14/BC$9*100 -> 9.4339623 | GC14: =BD14/BD$9*100 -> 15.09434 | GD14: =BF14/BF$9*100 -> 17.085427 | GE14: =BG14/BG$9*100 -> 7.0351759 | GF14: =BI14/BI$9*100 -> 9.5890411 | GG14: =BJ14/BJ$9*100 -> 15.753425 | GH14: =BL14/BL$9*100 -> 7.6433121 | GI14: =BM14/BM$9*100 -> 4.4585987 | GJ14: =BO14/BO$9*100 -> 12.820513 | GK14: =BP14/BP$9*100 -> 17.948718 | GL14: =BR14/BR$9*100 -> 4.5226131 | GM14: =BS14/BS$9*100 -> 2.5125628 | GO14: =$AM14 -> 3 | GP14: =FT14 -> 9.1428571 | GQ14: =GQ$6*(1+GQ$5*(-1)^$FQ14)*EXP(-$FQ14/GQ$4) -> 7.2362968 | GR14: =(GP14-GQ14)^2 -> 3.6349725 | GS14: =EXP($FQ14/$JG$4)*GP14 -> 18.428668 | GT14: =EXP($FQ14/$JG$4)*(-1)^$FQ14*GP14 -> -18.428668 | GU14: =(-1)^GO14*GP14 -> -9.1428571 | GW14: =$AM14 -> 3 | GX14: =FX14 -> 8.8235294 | GY14: =GY$6*(1+GY$5*(-1)^$FQ14)*EXP(-$FQ14/GY$4) -> 7.2362968 | GZ14: =(GX14-GY14)^2 -> 2.5193075 | HA14: =EXP($FQ14/$JG$4)*GX14 -> 17.78502 | HB14: =EXP($FQ14/$JG$4)*(-1)^$FQ14*GX14 -> -17.78502 | HC14: =(-1)^GW14*GX14 -> -8.8235294 | HE14: =$AM14 -> 3 | HF14: =GB14 -> 9.4339623 | HG14: =HG$6*(1+HG$5*(-1)^$FQ14)*EXP(-$FQ14/HG$4) -> 7.2362968 | HH14: =(HF14-HG14)^2 -> 4.8297336 | HI14: =EXP($FQ14/$JG$4)*HF14 -> 19.01543 | HJ14: =EXP($FQ14/$JG$4)*(-1)^$FQ14*HF14 -> -19.01543 | HK14: =(-1)^HE14*HF14 -> -9.4339623 | HM14: =$AM14 -> 3 | HN14: =GF14 -> 9.5890411 | HO14: =HO$6*(1+HO$5*(-1)^$FQ14)*EXP(-$FQ14/HO$4) -> 6.016404 | HP14: =(HN14-HO14)^2 -> 12.763736 | HQ14: =EXP($FQ14/$JG$4)*HN14 -> 19.328013 | HR14: =EXP($FQ14/$JG$4)*(-1)^$FQ14*HN14 -> -19.328013 | HS14: =(-1)^HM14*HN14 -> -9.5890411 | HU14: =$AM14 -> 3 | HV14: =GJ14 -> 12.820513 | HW14: =HW$6*(1+HW$5*(-1)^$FQ14)*EXP(-$FQ14/HW$4) -> 8.2800561 | HX14: =(HV14-HW14)^2 -> 20.615747 | HY14: =EXP($FQ14/$JG$4)*HV14 -> 25.841482 | HZ14: =EXP($FQ14/$JG$4)*(-1)^$FQ14*HV14 -> -25.841482 | IA14: =(-1)^HU14*HV14 -> -12.820513 | IB14: 15.009924 | ID14: =$AM14 -> 3 | IE14: =FZ14 -> 17.766497 | IF14: =IF$6*(1+IF$5*(-1)^$FQ14)*EXP(-$FQ14/IF$4) -> 10.448724 | IG14: =(IE14-IF14)^2 -> 53.549805 | IH14: =EXP($FQ14/$JG$4)*IE14 -> 35.810785 | II14: =EXP($FQ14/$JG$4)*(-1)^$FQ14*IE14 -> -35.810785 | IJ14: =(-1)^ID14*IE14 -> -17.766497 | IK14: 14.681435 | IM14: =$AM14 -> 3 | IN14: =GD14 -> 17.085427 | IO14: =IO$6*(1+IO$5*(-1)^$FQ14)*EXP(-$FQ14/IO$4) -> 9.3316696 | IP14: =(IN14-IO14)^2 -> 60.120757 | IQ14: =EXP($FQ14/$JG$4)*IN14 -> 34.437995 | IR14: =EXP($FQ14/$JG$4)*(-1)^$FQ14*IN14 -> -34.437995 | IS14: =(-1)^IM14*IN14 -> -17.085427 | IT14: 16.559852 | IV14: =$AM14 -> 3 | IW14: =GH14 -> 7.6433121 | IX14: =IX$6*(1+IX$5*(-1)^$FQ14)*EXP(-$FQ14/IX$4) -> 5.1753323 | IY14: =(IW14-IX14)^2 -> 6.0909244 | IZ14: =EXP($FQ14/$JG$4)*IW14 -> 15.406132 | JA14: =EXP($FQ14/$JG$4)*(-1)^$FQ14*IW14 -> -15.406132 | JB14: =(-1)^IV14*IW14 -> -7.6433121 | JC14: 20.313364 | JE14: =$AM14 -> 3 | JF14: =GL14 -> 4.5226131 | JG14: =JG$6*(1+JG$5*(-1)^$FQ14)*EXP(-$FQ14/JG$4) -> 3.7837088 | JH14: =(JF14-JG14)^2 -> 0.54597957 | JI14: =EXP($FQ14/$JG$4)*JF14 -> 9.1159399 | JJ14: =EXP($FQ14/$JG$4)*(-1)^$FQ14*JF14 -> -9.1159399 | JK14: =(-1)^JE14*JF14 -> -4.5226131 | JL14: 23.404138 | JO14: =$AM14 -> 3 | JP14: =GM14 -> 2.5125628 | JQ14: =JQ$6*(1+JQ$5*(-1)^$FQ14)*EXP(-$FQ14/JQ$4) -> 2.1550971 | JR14: =(JP14-JQ14)^2 -> 0.12778174 | JS14: =EXP($FQ14/$JG$4)*JP14 -> 5.0644111 | JT14: =EXP($FQ14/$JG$4)*(-1)^$FQ14*JP14 -> -5.0644111 | JU14: =(-1)^JO14*JP14 -> -2.5125628
A15: 2 | B15: 2 | C15: =B15-A15 -> 0 | D15: 1 | E15: 1 | F15: =E15-D15 -> 0 | G15: 1 | H15: 1 | I15: =H15-G15 -> 0 | J15: 2 | K15: 4 | L15: =K15-J15 -> 2 | M15: 6 | N15: 6 | O15: =N15-M15 -> 0 | P15: 1 | Q15: 3 | R15: =Q15-P15 -> 2 | S15: 4 | T15: 8 | U15: =T15-S15 -> 4 | V15: 1 | W15: 1 | X15: =W15-V15 -> 0 | Y15: 4 | Z15: 8 | AA15: =Z15-Y15 -> 4 | AB15: 6 | AC15: 10 | AD15: =AC15-AB15 -> 4 | AE15: 1 | AF15: 19 | AG15: =AF15-AE15 -> 18 | AM15: 4 | AN15: 1 | AO15: 1 | AP15: 0 | AQ15: 5 | AR15: 7 | AS15: 0 | AT15: 7 | AU15: 9 | AV15: 0 | AW15: 25 | AX15: 30 | AY15: 0 | AZ15: 41 | BA15: 47 | BB15: 4 | BC15: 19 | BD15: 32 | BE15: 2 | BF15: 38 | BG15: 34 | BH15: 22 | BI15: 22 | BJ15: 26 | BK15: 11 | BL15: 29 | BM15: 12 | BN15: 36 | BO15: 38 | BP15: 39 | BQ15: 23 | BR15: 47 | BS15: 28 | BT15: 33 | BW15: =$AM15 -> 4 | BX15: =MAX(BX14-AN15/AN$9*100,0) -> 0 | BY15: =MAX(BY14-AO15/AO$9*100,0) -> 0 | BZ15: =MAX(BZ14-AQ15/AQ$9*100,0) -> 0 | CA15: =MAX(CA14-AR15/AR$9*100,0) -> 0 | CB15: =CB$7*EXP(-$AM15/CB$8) -> 1.158967 | CC15: =(BZ15-CB15)^2 -> 1.3432044 | CD15: =MAX(CD14-AT15/AT$9*100,0) -> 0.43290043 | CE15: =MAX(CE14-AU15/AU$9*100,0) -> 0.43290043 | CF15: =CF$7*EXP(-$AM15/CF$8) -> 1.3218643 | CG15: =(CD15-CF15)^2 -> 0.79025681 | CH15: =$AM15 -> 4 | CI15: =MAX(CI14-AW15/AW$9*100,0) -> 2.2058824 | CJ15: =MAX(CJ14-AX15/AX$9*100,0) -> 8.8235294 | CK15: =CK$7*EXP(-$AM15/CK$8) -> 5.8297851 | CL15: =(CI15-CK15)^2 -> 13.132671 | CM15: =MAX(CM14-AZ15/AZ$9*100,0) -> 15.736041 | CN15: =MAX(CN14-BA15/BA$9*100,0) -> 24.365482 | CO15: =CO$7*EXP(-$AM15/CO$8) -> 19.438822 | CP15: =(CM15-CO15)^2 -> 13.710591 | CQ15: =$AM15 -> 4 | CR15: =MAX(CR14-BC15/BC$9*100,0) -> 5.0314465 | CS15: =MAX(CS14-BD15/BD$9*100,0) -> 17.610063 | CT15: =CT$7*EXP(-$AM15/CT$8) -> 6.3017432 | CU15: =(CR15-CT15)^2 -> 1.6136535 | CV15: =MAX(CV14-BF15/BF$9*100,0) -> 24.623116 | CW15: =MAX(CW14-BG15/BG$9*100,0) -> 57.286432 | CX15: =CX$7*EXP(-$AM15/CX$8) -> 25.813552 | CY15: =(CV15-CX15)^2 -> 1.4171396 | CZ15: =$AM15 -> 4 | DA15: =MAX(DA14-BI15/BI$9*100,0) -> 6.8493151 | DB15: =MAX(DB14-BJ15/BJ$9*100,0) -> 32.191781 | DC15: =DC$7*EXP(-$AM15/DC$8) -> 8.6319099 | DD15: =(DA15-DC15)^2 -> 3.1776442 | DE15: =MAX(DE14-BL15/BL$9*100,0) -> 44.585987 | DF15: =MAX(DF14-BM15/BM$9*100,0) -> 80.89172 | DG15: =DG$7*EXP(-$AM15/DG$8) -> 44.329473 | DH15: =(DE15-DG15)^2 -> 0.06579974 | DI15: =$AM15 -> 4 | DJ15: =MAX(DJ14-BO15/BO$9*100,0) -> 9.7435897 | DK15: =MAX(DK14-BP15/BP$9*100,0) -> 45.128205 | DL15: =DL$7*EXP(-$AM15/DL$8) -> 12.892523 | DM15: =(DJ15-DL15)^2 -> 9.9157833 | DN15: =MAX(DN14-BR15/BR$9*100,0) -> 35.678392 | DO15: =MAX(DO14-BS15/BS$9*100,0) -> 73.366834 | DP15: =DP$7*EXP(-$AM15/DP$8) -> 39.286328 | DQ15: =(DN15-DP15)^2 -> 13.017202 | DS15: =$AM15 -> 4 | DT15: =CA15 -> 0 | DU15: =DU$7*EXP(-DS15/DU$8) -> 2.638047 | DV15: =(DT15-DU15)^2 -> 6.9592918 | DX15: =$AM15 -> 4 | DY15: =CM15 -> 15.736041 | DZ15: =DZ$7*EXP(-DX15/DZ$8) -> 16.699922 | EA15: =(DY15-DZ15)^2 -> 0.92906647 | EC15: =$AM15 -> 4 | ED15: =CV15 -> 24.623116 | EE15: =EE$7*EXP(-EC15/EE$8) -> 24.756849 | EF15: =(ED15-EE15)^2 -> 0.017884554 | EH15: =$AM15 -> 4 | EI15: =DE15 -> 44.585987 | EJ15: =EJ$7*EXP(-EH15/EJ$8) -> 44.145533 | EK15: =(EI15-EJ15)^2 -> 0.19400001 | EM15: =AM15 -> 4 | EN15: =DN15 -> 35.678392 | EO15: =EO$7*EXP(-EM15/EO$8) -> 40.109023 | EP15: =(EN15-EO15)^2 -> 19.630495 | ER15: =$AM15 -> 4 | ES15: =BZ15 -> 0 | ET15: =ET$7*EXP(-ER15/ET$8) -> 1.5645236 | EU15: =(ES15-ET15)^2 -> 2.4477342 | EW15: =$AM15 -> 4 | EX15: =CI15 -> 2.2058824 | EY15: =EY$7*EXP(-EW15/EY$8) -> 3.0211991 | EZ15: =(EX15-EY15)^2 -> 0.66474144 | FB15: =$AM15 -> 4 | FC15: =CR15 -> 5.0314465 | FD15: =FD$7*EXP(-FB15/FD$8) -> 3.9442536 | FE15: =(FC15-FD15)^2 -> 1.1819884 | FG15: =$AM15 -> 4 | FH15: =DA15 -> 6.8493151 | FI15: =FI$7*EXP(-FG15/FI$8) -> 6.8206962 | FJ15: =(FH15-FI15)^2 -> 0.00081903925 | FL15: =EM15 -> 4 | FM15: =DJ15 -> 9.7435897 | FN15: =FN$7*EXP(-FL15/FN$8) -> 11.812187 | FO15: =(FM15-FN15)^2 -> 4.2790934 | FQ15: =AM15 -> 4 | FR15: =AN15/AN$9*100 -> 0.86956522 | FS15: =AO15/AO$9*100 -> 0.86956522 | FT15: =AQ15/AQ$9*100 -> 2.8571429 | FU15: =AR15/AR$9*100 -> 4 | FV15: =AT15/AT$9*100 -> 3.030303 | FW15: =AU15/AU$9*100 -> 3.8961039 | FX15: =AW15/AW$9*100 -> 18.382353 | FY15: =AX15/AX$9*100 -> 22.058824 | FZ15: =AZ15/AZ$9*100 -> 20.812183 | GA15: =BA15/BA$9*100 -> 23.857868 | GB15: =BC15/BC$9*100 -> 11.949686 | GC15: =BD15/BD$9*100 -> 20.125786 | GD15: =BF15/BF$9*100 -> 19.095477 | GE15: =BG15/BG$9*100 -> 17.085427 | GF15: =BI15/BI$9*100 -> 15.068493 | GG15: =BJ15/BJ$9*100 -> 17.808219 | GH15: =BL15/BL$9*100 -> 18.471338 | GI15: =BM15/BM$9*100 -> 7.6433121 | GJ15: =BO15/BO$9*100 -> 19.487179 | GK15: =BP15/BP$9*100 -> 20 | GL15: =BR15/BR$9*100 -> 23.61809 | GM15: =BS15/BS$9*100 -> 14.070352 | GO15: =$AM15 -> 4 | GP15: =FT15 -> 2.8571429 | GQ15: =GQ$6*(1+GQ$5*(-1)^$FQ15)*EXP(-$FQ15/GQ$4) -> 9.9110916 | GR15: =(GP15-GQ15)^2 -> 49.758193 | GS15: =EXP($FQ15/$JG$4)*GP15 -> 7.2746926 | GT15: =EXP($FQ15/$JG$4)*(-1)^$FQ15*GP15 -> 7.2746926 | GU15: =(-1)^GO15*GP15 -> 2.8571429 | GW15: =$AM15 -> 4 | GX15: =FX15 -> 18.382353 | GY15: =GY$6*(1+GY$5*(-1)^$FQ15)*EXP(-$FQ15/GY$4) -> 9.9110916 | GZ15: =(GX15-GY15)^2 -> 71.762268 | HA15: =EXP($FQ15/$JG$4)*GX15 -> 46.804089 | HB15: =EXP($FQ15/$JG$4)*(-1)^$FQ15*GX15 -> 46.804089 | HC15: =(-1)^GW15*GX15 -> 18.382353 | HE15: =$AM15 -> 4 | HF15: =GB15 -> 11.949686 | HG15: =HG$6*(1+HG$5*(-1)^$FQ15)*EXP(-$FQ15/HG$4) -> 9.9110916 | HH15: =(HF15-HG15)^2 -> 4.1558652 | HI15: =EXP($FQ15/$JG$4)*HF15 -> 30.425601 | HJ15: =EXP($FQ15/$JG$4)*(-1)^$FQ15*HF15 -> 30.425601 | HK15: =(-1)^HE15*HF15 -> 11.949686 | HM15: =$AM15 -> 4 | HN15: =GF15 -> 15.068493 | HO15: =HO$6*(1+HO$5*(-1)^$FQ15)*EXP(-$FQ15/HO$4) -> 15.059889 | HP15: =(HN15-HO15)^2 -> 7.4036547e-05 | HQ15: =EXP($FQ15/$JG$4)*HN15 -> 38.36653 | HR15: =EXP($FQ15/$JG$4)*(-1)^$FQ15*HN15 -> 38.36653 | HS15: =(-1)^HM15*HN15 -> 15.068493 | HU15: =$AM15 -> 4 | HV15: =GJ15 -> 19.487179 | HW15: =HW$6*(1+HW$5*(-1)^$FQ15)*EXP(-$FQ15/HW$4) -> 15.958381 | HX15: =(HV15-HW15)^2 -> 12.452418 | HY15: =EXP($FQ15/$JG$4)*HV15 -> 49.617134 | HZ15: =EXP($FQ15/$JG$4)*(-1)^$FQ15*HV15 -> 49.617134 | IA15: =(-1)^HU15*HV15 -> 19.487179 | IB15: 5.214548 | ID15: =$AM15 -> 4 | IE15: =FZ15 -> 20.812183 | IF15: =IF$6*(1+IF$5*(-1)^$FQ15)*EXP(-$FQ15/IF$4) -> 14.533274 | IG15: =(IE15-IF15)^2 -> 39.424697 | IH15: =EXP($FQ15/$JG$4)*IE15 -> 52.990781 | II15: =EXP($FQ15/$JG$4)*(-1)^$FQ15*IE15 -> 52.990781 | IJ15: =(-1)^ID15*IE15 -> 20.812183 | IK15: 7.941985 | IM15: =$AM15 -> 4 | IN15: =GD15 -> 19.095477 | IO15: =IO$6*(1+IO$5*(-1)^$FQ15)*EXP(-$FQ15/IO$4) -> 15.249487 | IP15: =(IN15-IO15)^2 -> 14.791643 | IQ15: =EXP($FQ15/$JG$4)*IN15 -> 48.619805 | IR15: =EXP($FQ15/$JG$4)*(-1)^$FQ15*IN15 -> 48.619805 | IS15: =(-1)^IM15*IN15 -> 19.095477 | IT15: 9.095202 | IV15: =$AM15 -> 4 | IW15: =GH15 -> 18.471338 | IX15: =IX$6*(1+IX$5*(-1)^$FQ15)*EXP(-$FQ15/IX$4) -> 16.558971 | IY15: =(IW15-IX15)^2 -> 3.6571473 | IZ15: =EXP($FQ15/$JG$4)*IW15 -> 47.030656 | JA15: =EXP($FQ15/$JG$4)*(-1)^$FQ15*IW15 -> 47.030656 | JB15: =(-1)^IV15*IW15 -> 18.471338 | JC15: 5.376399 | JE15: =$AM15 -> 4 | JF15: =GL15 -> 23.61809 | JG15: =JG$6*(1+JG$5*(-1)^$FQ15)*EXP(-$FQ15/JG$4) -> 19.61104 | JH15: =(JF15-JG15)^2 -> 16.056451 | JI15: =EXP($FQ15/$JG$4)*JF15 -> 60.135022 | JJ15: =EXP($FQ15/$JG$4)*(-1)^$FQ15*JF15 -> 60.135022 | JK15: =(-1)^JE15*JF15 -> 23.61809 | JL15: 3.551079 | JO15: =$AM15 -> 4 | JP15: =GM15 -> 14.070352 | JQ15: =JQ$6*(1+JQ$5*(-1)^$FQ15)*EXP(-$FQ15/JQ$4) -> 10.444378 | JR15: =(JP15-JQ15)^2 -> 13.147685 | JS15: =EXP($FQ15/$JG$4)*JP15 -> 35.82512 | JT15: =EXP($FQ15/$JG$4)*(-1)^$FQ15*JP15 -> 35.82512 | JU15: =(-1)^JO15*JP15 -> 14.070352
